<sdf version='1.7'>
  <model name='peter_robot'>
    <link name='base_link'>
      <inertial>
        <pose>0.005795 0.009474 0.02 0 -0 0</pose>
        <mass>3.00001</mass>
        <inertia>
          <ixx>0.000955919</ixx>
          <ixy>-0.00012201</ixy>
          <ixz>0.00049717</ixz>
          <iyy>0.000939279</iyy>
          <iyz>-0.000196143</iyz>
          <izz>0.000188143</izz>
        </inertia>
      </inertial>
      <collision name='base_link_collision'>
        <pose>0 0 0 0 -0 0</pose>
        <geometry>
          <mesh>
            <scale>1 1 1</scale>
            <uri>model://peter_robot/meshes/Cuerpo_link.STL</uri>
          </mesh>
        </geometry>
      </collision>
      <collision name='base_link_fixed_joint_lump__imu_link_collision_1'>
        <pose>0 0 0.005 -3.14159 0 -1.5708</pose>
        <geometry>
          <box>
            <size>0.1 0.1 0.05</size>
          </box>
        </geometry>
        <surface>
          <contact>
            <ode/>
          </contact>
          <friction>
            <ode/>
          </friction>
        </surface>
      </collision>
      <visual name='base_link_visual'>
        <pose>0 0 0 0 -0 0</pose>
        <geometry>
          <mesh>
            <scale>1 1 1</scale>
            <uri>model://peter_robot/meshes/Cuerpo_link.STL</uri>
          </mesh>
        </geometry>
      </visual>
      <visual name='base_link_fixed_joint_lump__imu_link_visual_1'>
        <pose>0 0 0.005 -3.14159 0 -1.5708</pose>
        <geometry>
          <box>
            <size>0.02 0.02 0.01</size>
          </box>
        </geometry>
      </visual>
      <gravity>1</gravity>
      <sensor name='imu_sensor' type='imu'>
        <always_on>1</always_on>
        <update_rate>100</update_rate>
        <visualize>1</visualize>
        <topic>__default_topic__</topic>
        <plugin name='imu_plugin' filename='libgazebo_ros_imu_sensor.so'>
          <topicName>imu</topicName>
          <bodyName>imu_link</bodyName>
          <updateRateHZ>10.0</updateRateHZ>
          <gaussianNoise>0.0</gaussianNoise>
          <xyzOffset>0 0 0</xyzOffset>
          <rpyOffset>0 0 0</rpyOffset>
          <frameName>imu_link</frameName>
        </plugin>
        <pose>0 0 0.005 -3.14159 0 -1.5708</pose>
      </sensor>
    </link>
    <joint name='CoxisLD_joint' type='revolute'>
      <pose relative_to='base_link'>-0.0558 0.0558 0.02 3.14159 -0 1.5708</pose>
      <parent>base_link</parent>
      <child>CoxisLD_link</child>
      <axis>
        <xyz>0 0 -1</xyz>
        <limit>
          <lower>0</lower>
          <upper>1.57</upper>
          <effort>300</effort>
          <velocity>3</velocity>
        </limit>
        <dynamics>
          <spring_reference>0</spring_reference>
          <spring_stiffness>0</spring_stiffness>
        </dynamics>
      </axis>
    </joint>
    <link name='CoxisLD_link'>
      <pose relative_to='CoxisLD_joint'>0 0 0 0 -0 0</pose>
      <inertial>
        <pose>0.014576 -0.000148 -0.00158 0 -0 0</pose>
        <mass>0.01983</mass>
        <inertia>
          <ixx>0.00332039</ixx>
          <ixy>0.00743744</ixy>
          <ixz>0.00564813</ixz>
          <iyy>0.00468185</iyy>
          <iyz>-0.00597634</iyz>
          <izz>0.00627797</izz>
        </inertia>
      </inertial>
      <collision name='CoxisLD_link_collision'>
        <pose>0 0 0 0 -0 0</pose>
        <geometry>
          <mesh>
            <scale>1 1 1</scale>
            <uri>model://peter_robot/meshes/CoxisLD_link.STL</uri>
          </mesh>
        </geometry>
      </collision>
      <visual name='CoxisLD_link_visual'>
        <pose>0 0 0 0 -0 0</pose>
        <geometry>
          <mesh>
            <scale>1 1 1</scale>
            <uri>model://peter_robot/meshes/CoxisLD_link.STL</uri>
          </mesh>
        </geometry>
      </visual>
    </link>
    <joint name='FemurLD_joint' type='revolute'>
      <pose relative_to='CoxisLD_link'>0.04455 0 -0.0046 -1.5708 0 0</pose>
      <parent>CoxisLD_link</parent>
      <child>FemurLD_link</child>
      <axis>
        <xyz>0 0 -1</xyz>
        <limit>
          <lower>-0.725</lower>
          <upper>0.725</upper>
          <effort>300</effort>
          <velocity>3</velocity>
        </limit>
        <dynamics>
          <spring_reference>0</spring_reference>
          <spring_stiffness>0</spring_stiffness>
        </dynamics>
      </axis>
    </joint>
    <link name='FemurLD_link'>
      <pose relative_to='FemurLD_joint'>0 0 0 0 -0 0</pose>
      <inertial>
        <pose>0.015845 0.000732 -0.002349 0 -0 0</pose>
        <mass>0.0267646</mass>
        <inertia>
          <ixx>0.00273727</ixx>
          <ixy>0.00319082</ixy>
          <ixz>0.00853423</ixz>
          <iyy>0.00735687</iyy>
          <iyz>-0.00326026</iyz>
          <izz>0.00754045</izz>
        </inertia>
      </inertial>
      <collision name='FemurLD_link_collision'>
        <pose>0 0 0 0 -0 0</pose>
        <geometry>
          <mesh>
            <scale>1 1 1</scale>
            <uri>model://peter_robot/meshes/FemurLD_link.STL</uri>
          </mesh>
        </geometry>
      </collision>
      <visual name='FemurLD_link_visual'>
        <pose>0 0 0 0 -0 0</pose>
        <geometry>
          <mesh>
            <scale>1 1 1</scale>
            <uri>model://peter_robot/meshes/FemurLD_link.STL</uri>
          </mesh>
        </geometry>
      </visual>
    </link>
    <joint name='TibiaLD_joint' type='revolute'>
      <pose relative_to='FemurLD_link'>0.05395 0 -0.0016 0 0 -1.5708</pose>
      <parent>FemurLD_link</parent>
      <child>TibiaLD_link</child>
      <axis>
        <xyz>0 0 -1</xyz>
        <limit>
          <lower>-1.57</lower>
          <upper>0.3925</upper>
          <effort>300</effort>
          <velocity>3</velocity>
        </limit>
        <dynamics>
          <spring_reference>0</spring_reference>
          <spring_stiffness>0</spring_stiffness>
        </dynamics>
      </axis>
    </joint>
    <link name='TibiaLD_link'>
      <pose relative_to='TibiaLD_joint'>0 0 0 0 -0 0</pose>
      <inertial>
        <pose>0.030334 -0.006465 0.000537 0 -0 0</pose>
        <mass>0.0203567</mass>
        <inertia>
          <ixx>0.00107531</ixx>
          <ixy>0.00408155</ixy>
          <ixz>-0.00720236</ixz>
          <iyy>0.0035902</iyy>
          <iyz>0.0080609</iyz>
          <izz>0.00372276</izz>
        </inertia>
      </inertial>
      <collision name='TibiaLD_link_collision'>
        <pose>0 0 0 0 -0 0</pose>
        <geometry>
          <mesh>
            <scale>1 1 1</scale>
            <uri>model://peter_robot/meshes/TibiaLD_link.STL</uri>
          </mesh>
        </geometry>
      </collision>
      <visual name='TibiaLD_link_visual'>
        <pose>0 0 0 0 -0 0</pose>
        <geometry>
          <mesh>
            <scale>1 1 1</scale>
            <uri>model://peter_robot/meshes/TibiaLD_link.STL</uri>
          </mesh>
        </geometry>
      </visual>
    </link>
    <joint name='RuedaLD_joint' type='revolute'>
      <pose relative_to='TibiaLD_link'>0.07225 0 -0.0007 0 -1.5708 0</pose>
      <parent>TibiaLD_link</parent>
      <child>RuedaLD_link</child>
      <axis>
        <xyz>0 0 -1</xyz>
        <limit>
          <lower>-1e+16</lower>
          <upper>1e+16</upper>
        </limit>
        <dynamics>
          <spring_reference>0</spring_reference>
          <spring_stiffness>0</spring_stiffness>
        </dynamics>
      </axis>
    </joint>
    <link name='RuedaLD_link'>
      <pose relative_to='RuedaLD_joint'>0 0 0 0 -0 0</pose>
      <inertial>
        <pose>0.002278 -0.002548 -0.006319 0 -0 0</pose>
        <mass>0.0405034</mass>
        <inertia>
          <ixx>0.00517414</ixx>
          <ixy>0.00684572</ixy>
          <ixz>-0.00213782</ixz>
          <iyy>0.00517414</iyy>
          <iyz>-0.00660691</iyz>
          <izz>0.00972991</izz>
        </inertia>
      </inertial>
      <collision name='RuedaLD_link_collision'>
        <pose>0 0 0 0 -0 0</pose>
        <geometry>
          <mesh>
            <scale>1 1 1</scale>
            <uri>model://peter_robot/meshes/RuedaLD_link.STL</uri>
          </mesh>
        </geometry>
      </collision>
      <visual name='RuedaLD_link_visual'>
        <pose>0 0 0 0 -0 0</pose>
        <geometry>
          <mesh>
            <scale>1 1 1</scale>
            <uri>model://peter_robot/meshes/RuedaLD_link.STL</uri>
          </mesh>
        </geometry>
      </visual>
    </link>
    <joint name='CoxisLU_joint' type='revolute'>
      <pose relative_to='base_link'>0.0558 0.0558 0.02 -3.14159 -0 1.5708</pose>
      <parent>base_link</parent>
      <child>CoxisLU_link</child>
      <axis>
        <xyz>0 0 -1</xyz>
        <limit>
          <lower>-1.57</lower>
          <upper>0</upper>
          <effort>300</effort>
          <velocity>3</velocity>
        </limit>
        <dynamics>
          <spring_reference>0</spring_reference>
          <spring_stiffness>0</spring_stiffness>
        </dynamics>
      </axis>
    </joint>
    <link name='CoxisLU_link'>
      <pose relative_to='CoxisLU_joint'>0 0 0 0 -0 0</pose>
      <inertial>
        <pose>0.014576 -0.000148 -0.00158 0 -0 0</pose>
        <mass>0.01983</mass>
        <inertia>
          <ixx>0.00332039</ixx>
          <ixy>0.00743744</ixy>
          <ixz>0.00564813</ixz>
          <iyy>0.00468185</iyy>
          <iyz>-0.00597634</iyz>
          <izz>0.00627797</izz>
        </inertia>
      </inertial>
      <collision name='CoxisLU_link_collision'>
        <pose>0 0 0 0 -0 0</pose>
        <geometry>
          <mesh>
            <scale>1 1 1</scale>
            <uri>model://peter_robot/meshes/CoxisLU_link.STL</uri>
          </mesh>
        </geometry>
      </collision>
      <visual name='CoxisLU_link_visual'>
        <pose>0 0 0 0 -0 0</pose>
        <geometry>
          <mesh>
            <scale>1 1 1</scale>
            <uri>model://peter_robot/meshes/CoxisLU_link.STL</uri>
          </mesh>
        </geometry>
      </visual>
    </link>
    <joint name='FemurLU_joint' type='revolute'>
      <pose relative_to='CoxisLU_link'>0.04455 0 -0.0046 -1.5708 0 0</pose>
      <parent>CoxisLU_link</parent>
      <child>FemurLU_link</child>
      <axis>
        <xyz>0 0 -1</xyz>
        <limit>
          <lower>-0.785</lower>
          <upper>0.785</upper>
          <effort>300</effort>
          <velocity>3</velocity>
        </limit>
        <dynamics>
          <spring_reference>0</spring_reference>
          <spring_stiffness>0</spring_stiffness>
        </dynamics>
      </axis>
    </joint>
    <link name='FemurLU_link'>
      <pose relative_to='FemurLU_joint'>0 0 0 0 -0 0</pose>
      <inertial>
        <pose>0.015845 0.000732 -0.002349 0 -0 0</pose>
        <mass>0.0267646</mass>
        <inertia>
          <ixx>0.00273727</ixx>
          <ixy>0.00319082</ixy>
          <ixz>0.00853423</ixz>
          <iyy>0.00735687</iyy>
          <iyz>-0.00326026</iyz>
          <izz>0.00754045</izz>
        </inertia>
      </inertial>
      <collision name='FemurLU_link_collision'>
        <pose>0 0 0 0 -0 0</pose>
        <geometry>
          <mesh>
            <scale>1 1 1</scale>
            <uri>model://peter_robot/meshes/FemurLU_link.STL</uri>
          </mesh>
        </geometry>
      </collision>
      <visual name='FemurLU_link_visual'>
        <pose>0 0 0 0 -0 0</pose>
        <geometry>
          <mesh>
            <scale>1 1 1</scale>
            <uri>model://peter_robot/meshes/FemurLU_link.STL</uri>
          </mesh>
        </geometry>
      </visual>
    </link>
    <joint name='TibiaLU_joint' type='revolute'>
      <pose relative_to='FemurLU_link'>0.05395 0 -0.0016 0 0 -1.5708</pose>
      <parent>FemurLU_link</parent>
      <child>TibiaLU_link</child>
      <axis>
        <xyz>0 0 -1</xyz>
        <limit>
          <lower>-1.57</lower>
          <upper>0.3925</upper>
          <effort>300</effort>
          <velocity>3</velocity>
        </limit>
        <dynamics>
          <spring_reference>0</spring_reference>
          <spring_stiffness>0</spring_stiffness>
        </dynamics>
      </axis>
    </joint>
    <link name='TibiaLU_link'>
      <pose relative_to='TibiaLU_joint'>0 0 0 0 -0 0</pose>
      <inertial>
        <pose>0.030334 -0.006465 0.000537 0 -0 0</pose>
        <mass>0.0203567</mass>
        <inertia>
          <ixx>0.00107531</ixx>
          <ixy>0.00408213</ixy>
          <ixz>-0.00720236</ixz>
          <iyy>0.0035902</iyy>
          <iyz>0.0080605</iyz>
          <izz>0.00372276</izz>
        </inertia>
      </inertial>
      <collision name='TibiaLU_link_collision'>
        <pose>0 0 0 0 -0 0</pose>
        <geometry>
          <mesh>
            <scale>1 1 1</scale>
            <uri>model://peter_robot/meshes/TibiaLU_link.STL</uri>
          </mesh>
        </geometry>
      </collision>
      <visual name='TibiaLU_link_visual'>
        <pose>0 0 0 0 -0 0</pose>
        <geometry>
          <mesh>
            <scale>1 1 1</scale>
            <uri>model://peter_robot/meshes/TibiaLU_link.STL</uri>
          </mesh>
        </geometry>
      </visual>
    </link>
    <joint name='RuedaLU_joint' type='revolute'>
      <pose relative_to='TibiaLU_link'>0.07225 0 -0.0007 3.14159 -1.57079 3.14159</pose>
      <parent>TibiaLU_link</parent>
      <child>RuedaLU_link</child>
      <axis>
        <xyz>0 0 -1</xyz>
        <limit>
          <lower>-1e+16</lower>
          <upper>1e+16</upper>
        </limit>
        <dynamics>
          <spring_reference>0</spring_reference>
          <spring_stiffness>0</spring_stiffness>
        </dynamics>
      </axis>
    </joint>
    <link name='RuedaLU_link'>
      <pose relative_to='RuedaLU_joint'>0 0 0 0 -0 0</pose>
      <inertial>
        <pose>0.002278 -0.002548 -0.006319 0 -0 0</pose>
        <mass>0.0405034</mass>
        <inertia>
          <ixx>0.00517414</ixx>
          <ixy>0.00684572</ixy>
          <ixz>-0.00213782</ixz>
          <iyy>0.00517414</iyy>
          <iyz>-0.00660691</iyz>
          <izz>0.00972991</izz>
        </inertia>
      </inertial>
      <collision name='RuedaLU_link_collision'>
        <pose>0 0 0 0 -0 0</pose>
        <geometry>
          <mesh>
            <scale>1 1 1</scale>
            <uri>model://peter_robot/meshes/RuedaLU_link.STL</uri>
          </mesh>
        </geometry>
      </collision>
      <visual name='RuedaLU_link_visual'>
        <pose>0 0 0 0 -0 0</pose>
        <geometry>
          <mesh>
            <scale>1 1 1</scale>
            <uri>model://peter_robot/meshes/RuedaLU_link.STL</uri>
          </mesh>
        </geometry>
      </visual>
    </link>
    <joint name='CoxisRD_joint' type='revolute'>
      <pose relative_to='base_link'>-0.0558 -0.0558 0.02 -3.14159 0 -1.5708</pose>
      <parent>base_link</parent>
      <child>CoxisRD_link</child>
      <axis>
        <xyz>0 0 -1</xyz>
        <limit>
          <lower>-1.57</lower>
          <upper>0</upper>
          <effort>300</effort>
          <velocity>3</velocity>
        </limit>
        <dynamics>
          <spring_reference>0</spring_reference>
          <spring_stiffness>0</spring_stiffness>
        </dynamics>
      </axis>
    </joint>
    <link name='CoxisRD_link'>
      <pose relative_to='CoxisRD_joint'>0 0 0 0 -0 0</pose>
      <inertial>
        <pose>0.014576 -0.000148 -0.00158 0 -0 0</pose>
        <mass>0.01983</mass>
        <inertia>
          <ixx>0.00332039</ixx>
          <ixy>0.00743744</ixy>
          <ixz>0.00564813</ixz>
          <iyy>0.00468185</iyy>
          <iyz>-0.00597634</iyz>
          <izz>0.00627797</izz>
        </inertia>
      </inertial>
      <collision name='CoxisRD_link_collision'>
        <pose>0 0 0 0 -0 0</pose>
        <geometry>
          <mesh>
            <scale>1 1 1</scale>
            <uri>model://peter_robot/meshes/CoxisRD_link.STL</uri>
          </mesh>
        </geometry>
      </collision>
      <visual name='CoxisRD_link_visual'>
        <pose>0 0 0 0 -0 0</pose>
        <geometry>
          <mesh>
            <scale>1 1 1</scale>
            <uri>model://peter_robot/meshes/CoxisRD_link.STL</uri>
          </mesh>
        </geometry>
      </visual>
    </link>
    <joint name='FemurRD_joint' type='revolute'>
      <pose relative_to='CoxisRD_link'>0.04455 0 -0.0046 -1.5708 0 0</pose>
      <parent>CoxisRD_link</parent>
      <child>FemurRD_link</child>
      <axis>
        <xyz>0 0 -1</xyz>
        <limit>
          <lower>-0.785</lower>
          <upper>0.785</upper>
          <effort>300</effort>
          <velocity>3</velocity>
        </limit>
        <dynamics>
          <spring_reference>0</spring_reference>
          <spring_stiffness>0</spring_stiffness>
        </dynamics>
      </axis>
    </joint>
    <link name='FemurRD_link'>
      <pose relative_to='FemurRD_joint'>0 0 0 0 -0 0</pose>
      <inertial>
        <pose>0.015845 0.000732 -0.002349 0 -0 0</pose>
        <mass>0.0267646</mass>
        <inertia>
          <ixx>0.00273727</ixx>
          <ixy>0.00319082</ixy>
          <ixz>0.00853423</ixz>
          <iyy>0.00735687</iyy>
          <iyz>-0.00326026</iyz>
          <izz>0.00754045</izz>
        </inertia>
      </inertial>
      <collision name='FemurRD_link_collision'>
        <pose>0 0 0 0 -0 0</pose>
        <geometry>
          <mesh>
            <scale>1 1 1</scale>
            <uri>model://peter_robot/meshes/FemurRD_link.STL</uri>
          </mesh>
        </geometry>
      </collision>
      <visual name='FemurRD_link_visual'>
        <pose>0 0 0 0 -0 0</pose>
        <geometry>
          <mesh>
            <scale>1 1 1</scale>
            <uri>model://peter_robot/meshes/FemurRD_link.STL</uri>
          </mesh>
        </geometry>
      </visual>
    </link>
    <joint name='TibiaRD_joint' type='revolute'>
      <pose relative_to='FemurRD_link'>0.05395 0 0.0016 0 0 -1.5708</pose>
      <parent>FemurRD_link</parent>
      <child>TibiaRD_link</child>
      <axis>
        <xyz>0 0 -1</xyz>
        <limit>
          <lower>-1.57</lower>
          <upper>0.3925</upper>
          <effort>300</effort>
          <velocity>3</velocity>
        </limit>
        <dynamics>
          <spring_reference>0</spring_reference>
          <spring_stiffness>0</spring_stiffness>
        </dynamics>
      </axis>
    </joint>
    <link name='TibiaRD_link'>
      <pose relative_to='TibiaRD_joint'>0 0 0 0 -0 0</pose>
      <inertial>
        <pose>0.030334 -0.006465 -0.002663 0 -0 0</pose>
        <mass>0.0203567</mass>
        <inertia>
          <ixx>0.00107531</ixx>
          <ixy>0.00408284</ixy>
          <ixz>-0.00720237</ixz>
          <iyy>0.0035902</iyy>
          <iyz>0.00805995</iyz>
          <izz>0.00372276</izz>
        </inertia>
      </inertial>
      <collision name='TibiaRD_link_collision'>
        <pose>0 0 0 0 -0 0</pose>
        <geometry>
          <mesh>
            <scale>1 1 1</scale>
            <uri>model://peter_robot/meshes/TibiaRD_link.STL</uri>
          </mesh>
        </geometry>
      </collision>
      <visual name='TibiaRD_link_visual'>
        <pose>0 0 0 0 -0 0</pose>
        <geometry>
          <mesh>
            <scale>1 1 1</scale>
            <uri>model://peter_robot/meshes/TibiaRD_link.STL</uri>
          </mesh>
        </geometry>
      </visual>
    </link>
    <joint name='RuedaRD_joint' type='revolute'>
      <pose relative_to='TibiaRD_link'>0.07225 0 -0.0039 3.14159 1.57079 3.14159</pose>
      <parent>TibiaRD_link</parent>
      <child>RuedaRD_link</child>
      <axis>
        <xyz>0 0 -1</xyz>
        <limit>
          <lower>-1e+16</lower>
          <upper>1e+16</upper>
        </limit>
        <dynamics>
          <spring_reference>0</spring_reference>
          <spring_stiffness>0</spring_stiffness>
        </dynamics>
      </axis>
    </joint>
    <link name='RuedaRD_link'>
      <pose relative_to='RuedaRD_joint'>0 0 0 0 -0 0</pose>
      <inertial>
        <pose>-0.002278 0.002548 -0.006319 0 -0 0</pose>
        <mass>0.0405034</mass>
        <inertia>
          <ixx>0.00517414</ixx>
          <ixy>0.00684572</ixy>
          <ixz>0.00213782</ixz>
          <iyy>0.00517414</iyy>
          <iyz>0.00660691</iyz>
          <izz>0.00972991</izz>
        </inertia>
      </inertial>
      <collision name='RuedaRD_link_collision'>
        <pose>0 0 0 0 -0 0</pose>
        <geometry>
          <mesh>
            <scale>1 1 1</scale>
            <uri>model://peter_robot/meshes/RuedaRD_link.STL</uri>
          </mesh>
        </geometry>
      </collision>
      <visual name='RuedaRD_link_visual'>
        <pose>0 0 0 0 -0 0</pose>
        <geometry>
          <mesh>
            <scale>1 1 1</scale>
            <uri>model://peter_robot/meshes/RuedaRD_link.STL</uri>
          </mesh>
        </geometry>
      </visual>
    </link>
    <joint name='CoxisRU_joint' type='revolute'>
      <pose relative_to='base_link'>0.0558 -0.0558 0.02 -3.14159 0 -1.5708</pose>
      <parent>base_link</parent>
      <child>CoxisRU_link</child>
      <axis>
        <xyz>0 0 -1</xyz>
        <limit>
          <lower>0</lower>
          <upper>1.57</upper>
          <effort>300</effort>
          <velocity>3</velocity>
        </limit>
        <dynamics>
          <spring_reference>0</spring_reference>
          <spring_stiffness>0</spring_stiffness>
        </dynamics>
      </axis>
    </joint>
    <link name='CoxisRU_link'>
      <pose relative_to='CoxisRU_joint'>0 0 0 0 -0 0</pose>
      <inertial>
        <pose>0.014576 -0.000148 -0.00158 0 -0 0</pose>
        <mass>0.01983</mass>
        <inertia>
          <ixx>0.000332039</ixx>
          <ixy>0.00743743</ixy>
          <ixz>0.00564813</ixz>
          <iyy>0.00468185</iyy>
          <iyz>-0.00597634</iyz>
          <izz>0.00627797</izz>
        </inertia>
      </inertial>
      <collision name='CoxisRU_link_collision'>
        <pose>0 0 0 0 -0 0</pose>
        <geometry>
          <mesh>
            <scale>1 1 1</scale>
            <uri>model://peter_robot/meshes/CoxisRU_link.STL</uri>
          </mesh>
        </geometry>
      </collision>
      <visual name='CoxisRU_link_visual'>
        <pose>0 0 0 0 -0 0</pose>
        <geometry>
          <mesh>
            <scale>1 1 1</scale>
            <uri>model://peter_robot/meshes/CoxisRU_link.STL</uri>
          </mesh>
        </geometry>
      </visual>
    </link>
    <joint name='FemurRU_joint' type='revolute'>
      <pose relative_to='CoxisRU_link'>0.04455 0 -0.0046 -1.5708 0 0</pose>
      <parent>CoxisRU_link</parent>
      <child>FemurRU_link</child>
      <axis>
        <xyz>0 0 -1</xyz>
        <limit>
          <lower>-0.785</lower>
          <upper>0.785</upper>
          <effort>300</effort>
          <velocity>3</velocity>
        </limit>
        <dynamics>
          <spring_reference>0</spring_reference>
          <spring_stiffness>0</spring_stiffness>
        </dynamics>
      </axis>
    </joint>
    <link name='FemurRU_link'>
      <pose relative_to='FemurRU_joint'>0 0 0 0 -0 0</pose>
      <inertial>
        <pose>0.015845 0.000732 -0.002349 0 -0 0</pose>
        <mass>0.0267646</mass>
        <inertia>
          <ixx>0.00273727</ixx>
          <ixy>0.00319082</ixy>
          <ixz>0.00853423</ixz>
          <iyy>0.00735687</iyy>
          <iyz>-0.00326026</iyz>
          <izz>0.00754045</izz>
        </inertia>
      </inertial>
      <collision name='FemurRU_link_collision'>
        <pose>0 0 0 0 -0 0</pose>
        <geometry>
          <mesh>
            <scale>1 1 1</scale>
            <uri>model://peter_robot/meshes/FemurRU_link.STL</uri>
          </mesh>
        </geometry>
      </collision>
      <visual name='FemurRU_link_visual'>
        <pose>0 0 0 0 -0 0</pose>
        <geometry>
          <mesh>
            <scale>1 1 1</scale>
            <uri>model://peter_robot/meshes/FemurRU_link.STL</uri>
          </mesh>
        </geometry>
      </visual>
    </link>
    <joint name='TibiaRU_joint' type='revolute'>
      <pose relative_to='FemurRU_link'>0.05395 0 0.0016 0 0 -1.5708</pose>
      <parent>FemurRU_link</parent>
      <child>TibiaRU_link</child>
      <axis>
        <xyz>0 0 -1</xyz>
        <limit>
          <lower>-1.57</lower>
          <upper>0.3925</upper>
          <effort>300</effort>
          <velocity>3</velocity>
        </limit>
        <dynamics>
          <spring_reference>0</spring_reference>
          <spring_stiffness>0</spring_stiffness>
        </dynamics>
      </axis>
    </joint>
    <link name='TibiaRU_link'>
      <pose relative_to='TibiaRU_joint'>0 0 0 0 -0 0</pose>
      <inertial>
        <pose>0.03032 -0.006461 -0.002649 0 -0 0</pose>
        <mass>0.0203667</mass>
        <inertia>
          <ixx>0.00107632</ixx>
          <ixy>0.00408213</ixy>
          <ixz>-0.00720236</ixz>
          <iyy>0.00359122</iyy>
          <iyz>0.00806051</iyz>
          <izz>0.00372377</izz>
        </inertia>
      </inertial>
      <collision name='TibiaRU_link_collision'>
        <pose>0 0 0 0 -0 0</pose>
        <geometry>
          <mesh>
            <scale>1 1 1</scale>
            <uri>model://peter_robot/meshes/TibiaRU_link.STL</uri>
          </mesh>
        </geometry>
      </collision>
      <collision name='TibiaRU_link_fixed_joint_lump__TibiaRU_Bump_link_collision_1'>
        <pose>0 0 0.005 -3.14159 0 -1.5708</pose>
        <geometry>
          <box>
            <size>0.06 0.06 0.06</size>
          </box>
        </geometry>
        <surface>
          <contact>
            <ode/>
          </contact>
          <friction>
            <ode/>
          </friction>
        </surface>
      </collision>
      <visual name='TibiaRU_link_visual'>
        <pose>0 0 0 0 -0 0</pose>
        <geometry>
          <mesh>
            <scale>1 1 1</scale>
            <uri>model://peter_robot/meshes/TibiaRU_link.STL</uri>
          </mesh>
        </geometry>
      </visual>
      <visual name='TibiaRU_link_fixed_joint_lump__TibiaRU_Bump_link_visual_1'>
        <pose>0 0 0.005 -3.14159 0 -1.5708</pose>
        <geometry>
          <box>
            <size>0.06 0.06 0.06</size>
          </box>
        </geometry>
      </visual>
      <self_collide>1</self_collide>
      <sensor name='TibiaRU_bumper' type='contact'>
        <plugin name='gazebo_ros_bumper_controller' filename='libgazebo_ros_bumper.so'>
          <bumperTopicName>bumper_TibiaRU</bumperTopicName>
          <contact>
            <collision>TibiaRU_link_fixed_joint_lump__TibiaRU_Bump_link_collision_1</collision>
          </contact>
          <frameName>world</frameName>
        </plugin>
        <pose>0 0 0.005 -3.14159 0 -1.5708</pose>
        <alwaysOn>1</alwaysOn>
        <updateRate>15.0</updateRate>
      </sensor>
    </link>
    <joint name='RuedaRU_joint' type='revolute'>
      <pose relative_to='TibiaRU_link'>0.07225 0 -0.0039 3.14159 1.57079 3.14159</pose>
      <parent>TibiaRU_link</parent>
      <child>RuedaRU_link</child>
      <axis>
        <xyz>0 0 -1</xyz>
        <limit>
          <effort>300</effort>
          <velocity>3</velocity>
          <lower>-1e+16</lower>
          <upper>1e+16</upper>
        </limit>
        <dynamics>
          <spring_reference>0</spring_reference>
          <spring_stiffness>0</spring_stiffness>
        </dynamics>
      </axis>
    </joint>
    <link name='RuedaRU_link'>
      <pose relative_to='RuedaRU_joint'>0 0 0 0 -0 0</pose>
      <inertial>
        <pose>-0.002278 0.002548 -0.006319 0 -0 0</pose>
        <mass>0.0405034</mass>
        <inertia>
          <ixx>0.00517414</ixx>
          <ixy>0.00684572</ixy>
          <ixz>0.00213782</ixz>
          <iyy>0.00517414</iyy>
          <iyz>0.00660691</iyz>
          <izz>0.00972991</izz>
        </inertia>
      </inertial>
      <collision name='RuedaRU_link_collision'>
        <pose>0 0 0 0 -0 0</pose>
        <geometry>
          <mesh>
            <scale>1 1 1</scale>
            <uri>model://peter_robot/meshes/RuedaRU_link.STL</uri>
          </mesh>
        </geometry>
      </collision>
      <visual name='RuedaRU_link_visual'>
        <pose>0 0 0 0 -0 0</pose>
        <geometry>
          <mesh>
            <scale>1 1 1</scale>
            <uri>model://peter_robot/meshes/RuedaRU_link.STL</uri>
          </mesh>
        </geometry>
      </visual>
    </link>
  </model>
</sdf>
