<sdf version='1.7'>
  <model name='peter_robot'>
    <link name='base_link'>
      <inertial>
        <pose>0 0 0.02 0 -0 0</pose>
        <mass>3.0</mass>
        <inertia>
          <ixx>9.54916e-05</ixx>
          <ixy>-1.22009e-20</ixy>
          <ixz>4.97171e-23</ixz>
          <iyy>9.38276e-05</iyy>
          <iyz>-1.96141e-22</iyz>
          <izz>0.000187141</izz>
        </inertia>
      </inertial>
      <collision name='base_link_collision'>
        <pose>0 0 0 0 -0 0</pose>
        <geometry>
          <mesh>
            <scale>1 1 1</scale>
            <uri>model://peter_robot/meshes/Cuerpo_link.STL</uri>
          </mesh>
        </geometry>
      </collision>
      <visual name='base_link_visual'>
        <pose>0 0 0 0 -0 0</pose>
        <geometry>
          <mesh>
            <scale>1 1 1</scale>
            <uri>model://peter_robot/meshes/Cuerpo_link.STL</uri>
          </mesh>
        </geometry>
      </visual>
    </link>
    <joint name='CoxisLD_joint' type='revolute'>
      <pose relative_to='base_link'>-0.0558 0.0558 0.02 3.14159 -0 1.5708</pose>
      <parent>base_link</parent>
      <child>CoxisLD_link</child>
      <axis>
        <xyz>0 0 -1</xyz>
        <limit>
          <lower>0</lower>
          <upper>1.57</upper>
          <effort>300</effort>
          <velocity>3</velocity>
        </limit>
        <dynamics>
          <spring_reference>0</spring_reference>
          <spring_stiffness>0</spring_stiffness>
        </dynamics>
      </axis>
    </joint>
    <link name='CoxisLD_link'>
      <pose relative_to='CoxisLD_joint'>0 0 0 0 -0 0</pose>
      <inertial>
        <pose>0.014576 -0.000148 -0.00158 0 -0 0</pose>
        <mass>0.01983</mass>
        <inertia>
          <ixx>3.32039e-06</ixx>
          <ixy>7.43744e-08</ixy>
          <ixz>5.64813e-08</ixz>
          <iyy>4.68185e-06</iyy>
          <iyz>-5.97634e-10</iyz>
          <izz>6.27797e-06</izz>
        </inertia>
      </inertial>
      <collision name='CoxisLD_link_collision'>
        <pose>0 0 0 0 -0 0</pose>
        <geometry>
          <mesh>
            <scale>1 1 1</scale>
            <uri>model://peter_robot/meshes/CoxisLD_link.STL</uri>
          </mesh>
        </geometry>
      </collision>
      <visual name='CoxisLD_link_visual'>
        <pose>0 0 0 0 -0 0</pose>
        <geometry>
          <mesh>
            <scale>1 1 1</scale>
            <uri>model://peter_robot/meshes/CoxisLD_link.STL</uri>
          </mesh>
        </geometry>
      </visual>
    </link>
    <joint name='FemurLD_joint' type='revolute'>
      <pose relative_to='CoxisLD_link'>0.04455 0 -0.0046 -1.5708 0 0</pose>
      <parent>CoxisLD_link</parent>
      <child>FemurLD_link</child>
      <axis>
        <xyz>0 0 -1</xyz>
        <limit>
          <lower>-0.725</lower>
          <upper>0.725</upper>
          <effort>300</effort>
          <velocity>3</velocity>
        </limit>
        <dynamics>
          <spring_reference>0</spring_reference>
          <spring_stiffness>0</spring_stiffness>
        </dynamics>
      </axis>
    </joint>
    <link name='FemurLD_link'>
      <pose relative_to='FemurLD_joint'>0 0 0 0 -0 0</pose>
      <inertial>
        <pose>0.015845 0.000732 -0.002349 0 -0 0</pose>
        <mass>0.0267646</mass>
        <inertia>
          <ixx>2.73727e-06</ixx>
          <ixy>3.19082e-07</ixy>
          <ixz>8.53423e-07</ixz>
          <iyy>7.35687e-06</iyy>
          <iyz>-3.26026e-08</iyz>
          <izz>7.54045e-06</izz>
        </inertia>
      </inertial>
      <collision name='FemurLD_link_collision'>
        <pose>0 0 0 0 -0 0</pose>
        <geometry>
          <mesh>
            <scale>1 1 1</scale>
            <uri>model://peter_robot/meshes/FemurLD_link.STL</uri>
          </mesh>
        </geometry>
      </collision>
      <visual name='FemurLD_link_visual'>
        <pose>0 0 0 0 -0 0</pose>
        <geometry>
          <mesh>
            <scale>1 1 1</scale>
            <uri>model://peter_robot/meshes/FemurLD_link.STL</uri>
          </mesh>
        </geometry>
      </visual>
    </link>
    <joint name='TibiaLD_joint' type='revolute'>
      <pose relative_to='FemurLD_link'>0.05395 0 -0.0016 0 0 -1.5708</pose>
      <parent>FemurLD_link</parent>
      <child>TibiaLD_link</child>
      <axis>
        <xyz>0 0 -1</xyz>
        <limit>
          <lower>-1.57</lower>
          <upper>0.3925</upper>
          <effort>300</effort>
          <velocity>3</velocity>
        </limit>
        <dynamics>
          <spring_reference>0</spring_reference>
          <spring_stiffness>0</spring_stiffness>
        </dynamics>
      </axis>
    </joint>
    <link name='TibiaLD_link'>
      <pose relative_to='TibiaLD_joint'>0 0 0 0 -0 0</pose>
      <inertial>
        <pose>0.030334 -6e-06 0.000537 0 -0 0</pose>
        <mass>0.0203567</mass>
        <inertia>
          <ixx>1.07531e-06</ixx>
          <ixy>4.08155e-12</ixy>
          <ixz>-7.20236e-08</ixz>
          <iyy>3.5902e-06</iyy>
          <iyz>8.0609e-12</iyz>
          <izz>3.72276e-06</izz>
        </inertia>
      </inertial>
      <collision name='TibiaLD_link_collision'>
        <pose>0 0 0 0 -0 0</pose>
        <geometry>
          <mesh>
            <scale>1 1 1</scale>
            <uri>model://peter_robot/meshes/TibiaLD_link.STL</uri>
          </mesh>
        </geometry>
      </collision>
      <visual name='TibiaLD_link_visual'>
        <pose>0 0 0 0 -0 0</pose>
        <geometry>
          <mesh>
            <scale>1 1 1</scale>
            <uri>model://peter_robot/meshes/TibiaLD_link.STL</uri>
          </mesh>
        </geometry>
      </visual>
    </link>
    <joint name='RuedaLD_joint' type='revolute'>
      <pose relative_to='TibiaLD_link'>0.07225 0 -0.0007 0 -1.5708 0</pose>
      <parent>TibiaLD_link</parent>
      <child>RuedaLD_link</child>
      <axis>
        <xyz>0 0 -1</xyz>
        <limit>
          <lower>-1e+16</lower>
          <upper>1e+16</upper>
        </limit>
        <dynamics>
          <spring_reference>0</spring_reference>
          <spring_stiffness>0</spring_stiffness>
        </dynamics>
      </axis>
    </joint>
    <link name='RuedaLD_link'>
      <pose relative_to='RuedaLD_joint'>0 0 0 0 -0 0</pose>
      <inertial>
        <pose>0 -0 -0 0 -0 0</pose>
        <mass>0.0405034</mass>
        <inertia>
          <ixx>5.17414e-06</ixx>
          <ixy>6.84572e-13</ixy>
          <ixz>-2.13782e-14</ixz>
          <iyy>5.17414e-06</iyy>
          <iyz>-6.60691e-15</iyz>
          <izz>9.72991e-06</izz>
        </inertia>
      </inertial>
      <collision name='RuedaLD_link_collision'>
        <pose>0 0 0 0 -0 0</pose>
        <geometry>
          <mesh>
            <scale>1 1 1</scale>
            <uri>model://peter_robot/meshes/RuedaLD_link.STL</uri>
          </mesh>
        </geometry>
      </collision>
      <visual name='RuedaLD_link_visual'>
        <pose>0 0 0 0 -0 0</pose>
        <geometry>
          <mesh>
            <scale>1 1 1</scale>
            <uri>model://peter_robot/meshes/RuedaLD_link.STL</uri>
          </mesh>
        </geometry>
      </visual>
    </link>
    <joint name='CoxisLU_joint' type='revolute'>
      <pose relative_to='base_link'>0.0558 0.0558 0.02 -3.14159 -0 1.5708</pose>
      <parent>base_link</parent>
      <child>CoxisLU_link</child>
      <axis>
        <xyz>0 0 -1</xyz>
        <limit>
          <lower>-1.57</lower>
          <upper>0</upper>
          <effort>300</effort>
          <velocity>3</velocity>
        </limit>
        <dynamics>
          <spring_reference>0</spring_reference>
          <spring_stiffness>0</spring_stiffness>
        </dynamics>
      </axis>
    </joint>
    <link name='CoxisLU_link'>
      <pose relative_to='CoxisLU_joint'>0 0 0 0 -0 0</pose>
      <inertial>
        <pose>0.014576 -0.000148 -0.00158 0 -0 0</pose>
        <mass>0.01983</mass>
        <inertia>
          <ixx>3.32039e-06</ixx>
          <ixy>7.43744e-08</ixy>
          <ixz>5.64813e-08</ixz>
          <iyy>4.68185e-06</iyy>
          <iyz>-5.97634e-10</iyz>
          <izz>6.27797e-06</izz>
        </inertia>
      </inertial>
      <collision name='CoxisLU_link_collision'>
        <pose>0 0 0 0 -0 0</pose>
        <geometry>
          <mesh>
            <scale>1 1 1</scale>
            <uri>model://peter_robot/meshes/CoxisLU_link.STL</uri>
          </mesh>
        </geometry>
      </collision>
      <visual name='CoxisLU_link_visual'>
        <pose>0 0 0 0 -0 0</pose>
        <geometry>
          <mesh>
            <scale>1 1 1</scale>
            <uri>model://peter_robot/meshes/CoxisLU_link.STL</uri>
          </mesh>
        </geometry>
      </visual>
    </link>
    <joint name='FemurLU_joint' type='revolute'>
      <pose relative_to='CoxisLU_link'>0.04455 0 -0.0046 -1.5708 0 0</pose>
      <parent>CoxisLU_link</parent>
      <child>FemurLU_link</child>
      <axis>
        <xyz>0 0 -1</xyz>
        <limit>
          <lower>-0.785</lower>
          <upper>0.785</upper>
          <effort>300</effort>
          <velocity>3</velocity>
        </limit>
        <dynamics>
          <spring_reference>0</spring_reference>
          <spring_stiffness>0</spring_stiffness>
        </dynamics>
      </axis>
    </joint>
    <link name='FemurLU_link'>
      <pose relative_to='FemurLU_joint'>0 0 0 0 -0 0</pose>
      <inertial>
        <pose>0.015845 0.000732 -0.002349 0 -0 0</pose>
        <mass>0.0267646</mass>
        <inertia>
          <ixx>2.73727e-06</ixx>
          <ixy>3.19082e-07</ixy>
          <ixz>8.53423e-07</ixz>
          <iyy>7.35687e-06</iyy>
          <iyz>-3.26026e-08</iyz>
          <izz>7.54045e-06</izz>
        </inertia>
      </inertial>
      <collision name='FemurLU_link_collision'>
        <pose>0 0 0 0 -0 0</pose>
        <geometry>
          <mesh>
            <scale>1 1 1</scale>
            <uri>model://peter_robot/meshes/FemurLU_link.STL</uri>
          </mesh>
        </geometry>
      </collision>
      <visual name='FemurLU_link_visual'>
        <pose>0 0 0 0 -0 0</pose>
        <geometry>
          <mesh>
            <scale>1 1 1</scale>
            <uri>model://peter_robot/meshes/FemurLU_link.STL</uri>
          </mesh>
        </geometry>
      </visual>
    </link>
    <joint name='TibiaLU_joint' type='revolute'>
      <pose relative_to='FemurLU_link'>0.05395 0 -0.0016 0 0 -1.5708</pose>
      <parent>FemurLU_link</parent>
      <child>TibiaLU_link</child>
      <axis>
        <xyz>0 0 -1</xyz>
        <limit>
          <lower>-1.57</lower>
          <upper>0.3925</upper>
          <effort>300</effort>
          <velocity>3</velocity>
        </limit>
        <dynamics>
          <spring_reference>0</spring_reference>
          <spring_stiffness>0</spring_stiffness>
        </dynamics>
      </axis>
    </joint>
    <link name='TibiaLU_link'>
      <pose relative_to='TibiaLU_joint'>0 0 0 0 -0 0</pose>
      <inertial>
        <pose>0.030334 -6e-06 0.000537 0 -0 0</pose>
        <mass>0.0203567</mass>
        <inertia>
          <ixx>1.07531e-06</ixx>
          <ixy>4.08213e-12</ixy>
          <ixz>-7.20236e-08</ixz>
          <iyy>3.5902e-06</iyy>
          <iyz>8.0605e-12</iyz>
          <izz>3.72276e-06</izz>
        </inertia>
      </inertial>
      <collision name='TibiaLU_link_collision'>
        <pose>0 0 0 0 -0 0</pose>
        <geometry>
          <mesh>
            <scale>1 1 1</scale>
            <uri>model://peter_robot/meshes/TibiaLU_link.STL</uri>
          </mesh>
        </geometry>
      </collision>
      <visual name='TibiaLU_link_visual'>
        <pose>0 0 0 0 -0 0</pose>
        <geometry>
          <mesh>
            <scale>1 1 1</scale>
            <uri>model://peter_robot/meshes/TibiaLU_link.STL</uri>
          </mesh>
        </geometry>
      </visual>
    </link>
    <joint name='RuedaLU_joint' type='revolute'>
      <pose relative_to='TibiaLU_link'>0.07225 0 -0.0007 3.14159 -1.57079 3.14159</pose>
      <parent>TibiaLU_link</parent>
      <child>RuedaLU_link</child>
      <axis>
        <xyz>0 0 -1</xyz>
        <limit>
          <lower>-1e+16</lower>
          <upper>1e+16</upper>
        </limit>
        <dynamics>
          <spring_reference>0</spring_reference>
          <spring_stiffness>0</spring_stiffness>
        </dynamics>
      </axis>
    </joint>
    <link name='RuedaLU_link'>
      <pose relative_to='RuedaLU_joint'>0 0 0 0 -0 0</pose>
      <inertial>
        <pose>0 -0 -0 0 -0 0</pose>
        <mass>0.0405034</mass>
        <inertia>
          <ixx>5.17414e-06</ixx>
          <ixy>6.84572e-13</ixy>
          <ixz>-2.13782e-14</ixz>
          <iyy>5.17414e-06</iyy>
          <iyz>-6.60691e-15</iyz>
          <izz>9.72991e-06</izz>
        </inertia>
      </inertial>
      <collision name='RuedaLU_link_collision'>
        <pose>0 0 0 0 -0 0</pose>
        <geometry>
          <mesh>
            <scale>1 1 1</scale>
            <uri>model://peter_robot/meshes/RuedaLU_link.STL</uri>
          </mesh>
        </geometry>
      </collision>
      <visual name='RuedaLU_link_visual'>
        <pose>0 0 0 0 -0 0</pose>
        <geometry>
          <mesh>
            <scale>1 1 1</scale>
            <uri>model://peter_robot/meshes/RuedaLU_link.STL</uri>
          </mesh>
        </geometry>
      </visual>
    </link>
    <joint name='CoxisRD_joint' type='revolute'>
      <pose relative_to='base_link'>-0.0558 -0.0558 0.02 -3.14159 0 -1.5708</pose>
      <parent>base_link</parent>
      <child>CoxisRD_link</child>
      <axis>
        <xyz>0 0 -1</xyz>
        <limit>
          <lower>-1.57</lower>
          <upper>0</upper>
          <effort>300</effort>
          <velocity>3</velocity>
        </limit>
        <dynamics>
          <spring_reference>0</spring_reference>
          <spring_stiffness>0</spring_stiffness>
        </dynamics>
      </axis>
    </joint>
    <link name='CoxisRD_link'>
      <pose relative_to='CoxisRD_joint'>0 0 0 0 -0 0</pose>
      <inertial>
        <pose>0.014576 -0.000148 -0.00158 0 -0 0</pose>
        <mass>0.01983</mass>
        <inertia>
          <ixx>3.32039e-06</ixx>
          <ixy>7.43744e-08</ixy>
          <ixz>5.64813e-08</ixz>
          <iyy>4.68185e-06</iyy>
          <iyz>-5.97634e-10</iyz>
          <izz>6.27797e-06</izz>
        </inertia>
      </inertial>
      <collision name='CoxisRD_link_collision'>
        <pose>0 0 0 0 -0 0</pose>
        <geometry>
          <mesh>
            <scale>1 1 1</scale>
            <uri>model://peter_robot/meshes/CoxisRD_link.STL</uri>
          </mesh>
        </geometry>
      </collision>
      <visual name='CoxisRD_link_visual'>
        <pose>0 0 0 0 -0 0</pose>
        <geometry>
          <mesh>
            <scale>1 1 1</scale>
            <uri>model://peter_robot/meshes/CoxisRD_link.STL</uri>
          </mesh>
        </geometry>
      </visual>
    </link>
    <joint name='FemurRD_joint' type='revolute'>
      <pose relative_to='CoxisRD_link'>0.04455 0 -0.0046 -1.5708 0 0</pose>
      <parent>CoxisRD_link</parent>
      <child>FemurRD_link</child>
      <axis>
        <xyz>0 0 -1</xyz>
        <limit>
          <lower>-0.785</lower>
          <upper>0.785</upper>
          <effort>300</effort>
          <velocity>3</velocity>
        </limit>
        <dynamics>
          <spring_reference>0</spring_reference>
          <spring_stiffness>0</spring_stiffness>
        </dynamics>
      </axis>
    </joint>
    <link name='FemurRD_link'>
      <pose relative_to='FemurRD_joint'>0 0 0 0 -0 0</pose>
      <inertial>
        <pose>0.015845 0.000732 -0.002349 0 -0 0</pose>
        <mass>0.0267646</mass>
        <inertia>
          <ixx>2.73727e-06</ixx>
          <ixy>3.19082e-07</ixy>
          <ixz>8.53423e-07</ixz>
          <iyy>7.35687e-06</iyy>
          <iyz>-3.26026e-08</iyz>
          <izz>7.54045e-06</izz>
        </inertia>
      </inertial>
      <collision name='FemurRD_link_collision'>
        <pose>0 0 0 0 -0 0</pose>
        <geometry>
          <mesh>
            <scale>1 1 1</scale>
            <uri>model://peter_robot/meshes/FemurRD_link.STL</uri>
          </mesh>
        </geometry>
      </collision>
      <visual name='FemurRD_link_visual'>
        <pose>0 0 0 0 -0 0</pose>
        <geometry>
          <mesh>
            <scale>1 1 1</scale>
            <uri>model://peter_robot/meshes/FemurRD_link.STL</uri>
          </mesh>
        </geometry>
      </visual>
    </link>
    <joint name='TibiaRD_joint' type='revolute'>
      <pose relative_to='FemurRD_link'>0.05395 0 0.0016 0 0 -1.5708</pose>
      <parent>FemurRD_link</parent>
      <child>TibiaRD_link</child>
      <axis>
        <xyz>0 0 -1</xyz>
        <limit>
          <lower>-1.57</lower>
          <upper>0.3925</upper>
          <effort>300</effort>
          <velocity>3</velocity>
        </limit>
        <dynamics>
          <spring_reference>0</spring_reference>
          <spring_stiffness>0</spring_stiffness>
        </dynamics>
      </axis>
    </joint>
    <link name='TibiaRD_link'>
      <pose relative_to='TibiaRD_joint'>0 0 0 0 -0 0</pose>
      <inertial>
        <pose>0.030334 -6e-06 -0.002663 0 -0 0</pose>
        <mass>0.0203567</mass>
        <inertia>
          <ixx>1.07531e-06</ixx>
          <ixy>4.08284e-12</ixy>
          <ixz>-7.20237e-08</ixz>
          <iyy>3.5902e-06</iyy>
          <iyz>8.05995e-12</iyz>
          <izz>3.72276e-06</izz>
        </inertia>
      </inertial>
      <collision name='TibiaRD_link_collision'>
        <pose>0 0 0 0 -0 0</pose>
        <geometry>
          <mesh>
            <scale>1 1 1</scale>
            <uri>model://peter_robot/meshes/TibiaRD_link.STL</uri>
          </mesh>
        </geometry>
      </collision>
      <visual name='TibiaRD_link_visual'>
        <pose>0 0 0 0 -0 0</pose>
        <geometry>
          <mesh>
            <scale>1 1 1</scale>
            <uri>model://peter_robot/meshes/TibiaRD_link.STL</uri>
          </mesh>
        </geometry>
      </visual>
    </link>
    <joint name='RuedaRD_joint' type='revolute'>
      <pose relative_to='TibiaRD_link'>0.07225 0 -0.0039 3.14159 1.57079 3.14159</pose>
      <parent>TibiaRD_link</parent>
      <child>RuedaRD_link</child>
      <axis>
        <xyz>0 0 -1</xyz>
        <limit>
          <lower>-1e+16</lower>
          <upper>1e+16</upper>
        </limit>
        <dynamics>
          <spring_reference>0</spring_reference>
          <spring_stiffness>0</spring_stiffness>
        </dynamics>
      </axis>
    </joint>
    <link name='RuedaRD_link'>
      <pose relative_to='RuedaRD_joint'>0 0 0 0 -0 0</pose>
      <inertial>
        <pose>-0 0 -0 0 -0 0</pose>
        <mass>0.0405034</mass>
        <inertia>
          <ixx>5.17414e-06</ixx>
          <ixy>6.84572e-13</ixy>
          <ixz>2.13782e-14</ixz>
          <iyy>5.17414e-06</iyy>
          <iyz>6.60691e-15</iyz>
          <izz>9.72991e-06</izz>
        </inertia>
      </inertial>
      <collision name='RuedaRD_link_collision'>
        <pose>0 0 0 0 -0 0</pose>
        <geometry>
          <mesh>
            <scale>1 1 1</scale>
            <uri>model://peter_robot/meshes/RuedaRD_link.STL</uri>
          </mesh>
        </geometry>
      </collision>
      <visual name='RuedaRD_link_visual'>
        <pose>0 0 0 0 -0 0</pose>
        <geometry>
          <mesh>
            <scale>1 1 1</scale>
            <uri>model://peter_robot/meshes/RuedaRD_link.STL</uri>
          </mesh>
        </geometry>
      </visual>
    </link>
    <joint name='CoxisRU_joint' type='revolute'>
      <pose relative_to='base_link'>0.0558 -0.0558 0.02 -3.14159 0 -1.5708</pose>
      <parent>base_link</parent>
      <child>CoxisRU_link</child>
      <axis>
        <xyz>0 0 -1</xyz>
        <limit>
          <lower>0</lower>
          <upper>1.57</upper>
          <effort>300</effort>
          <velocity>3</velocity>
        </limit>
        <dynamics>
          <spring_reference>0</spring_reference>
          <spring_stiffness>0</spring_stiffness>
        </dynamics>
      </axis>
    </joint>
    <link name='CoxisRU_link'>
      <pose relative_to='CoxisRU_joint'>0 0 0 0 -0 0</pose>
      <inertial>
        <pose>0.014576 -0.000148 -0.00158 0 -0 0</pose>
        <mass>0.01983</mass>
        <inertia>
          <ixx>3.32039e-06</ixx>
          <ixy>7.43743e-08</ixy>
          <ixz>5.64813e-08</ixz>
          <iyy>4.68185e-06</iyy>
          <iyz>-5.97634e-10</iyz>
          <izz>6.27797e-06</izz>
        </inertia>
      </inertial>
      <collision name='CoxisRU_link_collision'>
        <pose>0 0 0 0 -0 0</pose>
        <geometry>
          <mesh>
            <scale>1 1 1</scale>
            <uri>model://peter_robot/meshes/CoxisRU_link.STL</uri>
          </mesh>
        </geometry>
      </collision>
      <visual name='CoxisRU_link_visual'>
        <pose>0 0 0 0 -0 0</pose>
        <geometry>
          <mesh>
            <scale>1 1 1</scale>
            <uri>model://peter_robot/meshes/CoxisRU_link.STL</uri>
          </mesh>
        </geometry>
      </visual>
    </link>
    <joint name='FemurRU_joint' type='revolute'>
      <pose relative_to='CoxisRU_link'>0.04455 0 -0.0046 -1.5708 0 0</pose>
      <parent>CoxisRU_link</parent>
      <child>FemurRU_link</child>
      <axis>
        <xyz>0 0 -1</xyz>
        <limit>
          <lower>-0.785</lower>
          <upper>0.785</upper>
          <effort>300</effort>
          <velocity>3</velocity>
        </limit>
        <dynamics>
          <spring_reference>0</spring_reference>
          <spring_stiffness>0</spring_stiffness>
        </dynamics>
      </axis>
    </joint>
    <link name='FemurRU_link'>
      <pose relative_to='FemurRU_joint'>0 0 0 0 -0 0</pose>
      <inertial>
        <pose>0.015845 0.000732 -0.002349 0 -0 0</pose>
        <mass>0.0267646</mass>
        <inertia>
          <ixx>2.73727e-06</ixx>
          <ixy>3.19082e-07</ixy>
          <ixz>8.53423e-07</ixz>
          <iyy>7.35687e-06</iyy>
          <iyz>-3.26026e-08</iyz>
          <izz>7.54045e-06</izz>
        </inertia>
      </inertial>
      <collision name='FemurRU_link_collision'>
        <pose>0 0 0 0 -0 0</pose>
        <geometry>
          <mesh>
            <scale>1 1 1</scale>
            <uri>model://peter_robot/meshes/FemurRU_link.STL</uri>
          </mesh>
        </geometry>
      </collision>
      <visual name='FemurRU_link_visual'>
        <pose>0 0 0 0 -0 0</pose>
        <geometry>
          <mesh>
            <scale>1 1 1</scale>
            <uri>model://peter_robot/meshes/FemurRU_link.STL</uri>
          </mesh>
        </geometry>
      </visual>
    </link>
    <joint name='TibiaRU_joint' type='revolute'>
      <pose relative_to='FemurRU_link'>0.05395 0 0.0016 0 0 -1.5708</pose>
      <parent>FemurRU_link</parent>
      <child>TibiaRU_link</child>
      <axis>
        <xyz>0 0 -1</xyz>
        <limit>
          <lower>-1.57</lower>
          <upper>0.3925</upper>
          <effort>300</effort>
          <velocity>3</velocity>
        </limit>
        <dynamics>
          <spring_reference>0</spring_reference>
          <spring_stiffness>0</spring_stiffness>
        </dynamics>
      </axis>
    </joint>
    <link name='TibiaRU_link'>
      <pose relative_to='TibiaRU_joint'>0 0 0 0 -0 0</pose>
      <inertial>
        <pose>0.030334 -6e-06 -0.002663 0 -0 0</pose>
        <mass>0.0203567</mass>
        <inertia>
          <ixx>1.07531e-06</ixx>
          <ixy>4.08213e-12</ixy>
          <ixz>-7.20236e-08</ixz>
          <iyy>3.5902e-06</iyy>
          <iyz>8.06052e-12</iyz>
          <izz>3.72276e-06</izz>
        </inertia>
      </inertial>
      <collision name='TibiaRU_link_collision'>
        <pose>0 0 0 0 -0 0</pose>
        <geometry>
          <mesh>
            <scale>1 1 1</scale>
            <uri>model://peter_robot/meshes/TibiaRU_link.STL</uri>
          </mesh>
        </geometry>
      </collision>
      <visual name='TibiaRU_link_visual'>
        <pose>0 0 0 0 -0 0</pose>
        <geometry>
          <mesh>
            <scale>1 1 1</scale>
            <uri>model://peter_robot/meshes/TibiaRU_link.STL</uri>
          </mesh>
        </geometry>
      </visual>
    </link>
    <joint name='RuedaRU_joint' type='revolute'>
      <pose relative_to='TibiaRU_link'>0.07225 0 -0.0039 3.14159 1.57079 3.14159</pose>
      <parent>TibiaRU_link</parent>
      <child>RuedaRU_link</child>
      <axis>
        <xyz>0 0 -1</xyz>
        <limit>
          <effort>300</effort>
          <velocity>3</velocity>
          <lower>-1e+16</lower>
          <upper>1e+16</upper>
        </limit>
        <dynamics>
          <spring_reference>0</spring_reference>
          <spring_stiffness>0</spring_stiffness>
        </dynamics>
      </axis>
    </joint>
    <link name='RuedaRU_link'>
      <pose relative_to='RuedaRU_joint'>0 0 0 0 -0 0</pose>
      <inertial>
        <pose>-0 0 -0 0 -0 0</pose>
        <mass>0.0405034</mass>
        <inertia>
          <ixx>5.17414e-06</ixx>
          <ixy>6.84572e-13</ixy>
          <ixz>2.13782e-14</ixz>
          <iyy>5.17414e-06</iyy>
          <iyz>6.60691e-15</iyz>
          <izz>9.72991e-06</izz>
        </inertia>
      </inertial>
      <collision name='RuedaRU_link_collision'>
        <pose>0 0 0 0 -0 0</pose>
        <geometry>
          <mesh>
            <scale>1 1 1</scale>
            <uri>model://peter_robot/meshes/RuedaRU_link.STL</uri>
          </mesh>
        </geometry>
      </collision>
      <visual name='RuedaRU_link_visual'>
        <pose>0 0 0 0 -0 0</pose>
        <geometry>
          <mesh>
            <scale>1 1 1</scale>
            <uri>model://peter_robot/meshes/RuedaRU_link.STL</uri>
          </mesh>
        </geometry>
      </visual>
    </link>
  </model>
</sdf>
