<?xml version="1.0" encoding="utf-8"?>
<!-- This URDF was automatically created by SolidWorks to URDF Exporter! Originally created by Stephen Brawner (brawner@gmail.com) 
     Commit Version: 1.6.0-4-g7f85cfe  Build Version: 1.6.7995.38578
     For more information, please see http://wiki.ros.org/sw_urdf_exporter -->
<robot name="Peter_3.0_completo" xmlns:xacro="http://www.ros.org/wiki/xacro">

  <xacro:include filename="peter_colors.xacro"/>

  <!-- MATERIALES -->

  <material name="base_color">
    <color rgba="${base_color}"/>
    <specular rgba="${specular}" />
    <shininess>${shininess}</shininess>
  </material>

  <material name="coxis_color">
    <color rgba="${coxis_color}"/>
    <specular rgba="${specular}" />
    <shininess>${shininess}</shininess>
  </material>

  <material name="femur_color">
    <color rgba="${femur_color}"/>
    <specular rgba="${specular}" />
    <shininess>${shininess}</shininess>
  </material>

  <material name="tibia_color">
    <color rgba="${tibia_color}"/>
    <specular rgba="${specular}" />
    <shininess>${shininess}</shininess>
  </material>

  <material name="rueda_color">
    <color rgba="${rueda_color}"/>
    <specular rgba="${specular}" />
    <shininess>${shininess}</shininess>
  </material>

  <material name="sensor_color">
    <color rgba="${sensor_color}"/>
    <specular rgba="${specular}" />
    <shininess>${shininess}</shininess>
  </material>

  <material name="headz_color">
    <color rgba="${headz_color}"/>
    <specular rgba="${specular}" />
    <shininess>${shininess}</shininess>
  </material>

  <material name="heady_color">
    <color rgba="${heady_color}"/>
    <specular rgba="${specular}" />
    <shininess>${shininess}</shininess>
  </material>

  <!-- Base Link -->
  <link
    name="base_link">
    <visual>
      <origin
        xyz="0 0 0"
        rpy="0 0 0" />
      <geometry>
        <mesh
          filename="file://$(find peter_robot)/meshes/base_link.STL" />
      </geometry>
      <material
        name="base_color">
      </material>
    </visual>
    <collision>
      <origin
        xyz="0 0 0"
        rpy="0 0 0" />
      <geometry>
        <mesh
          filename="file://$(find peter_robot)/meshes/base_link.STL" />
      </geometry>
    </collision>
  </link>

  <!-- IMU -->
  <link name="imu_link">
      <inertial>
          <mass value="0.1"/>  <!-- Masa del IMU -->
          <origin xyz="0 0 0" rpy="0 0 0"/>
          <inertia ixx="0.001" ixy="0" ixz="0" iyy="0.001" iyz="0" izz="0.001"/>
      </inertial>
      <visual>
          <origin xyz="0 0 0" rpy="0 0 0"/>
          <geometry>
              <box size="0.01 0.01 0.01"/>  <!-- Tamaño del IMU -->
          </geometry>
          <material name="sensor_color"/>
      </visual>
      <collision>
          <origin xyz="0 0 0" rpy="0 0 0"/>
          <geometry>
              <box size="0.01 0.01 0.01"/>
          </geometry>
      </collision>
  </link>

  <joint name="imu_joint" type="fixed">
      <parent link="base_link"/>
      <child link="imu_link"/>
      <origin xyz="0 0 0.01" rpy="0 0 0"/>  <!-- Posición relativa al base_link -->
  </joint>

  <!-- LIDAR -->
  <link name="lidar_link">
    <inertial>
      <origin
        xyz="9.81087993409124E-05 7.85641738580093E-05 -0.0107757447995264"
        rpy="0 0 0" />
      <mass
        value="0.0120321644827466" />
      <inertia
        ixx="2.21429850902999E-06"
        ixy="-3.38753438526488E-08"
        ixz="4.84631029572256E-09"
        iyy="2.13896937374521E-06"
        iyz="4.19024170674008E-09"
        izz="3.87805341770386E-06" />
    </inertial>
    <visual>
      <origin
        xyz="0 0 0"
        rpy="0 0 0" />
      <geometry>
        <mesh
          filename="file://$(find peter_robot)/meshes/lidar_link.STL" />
      </geometry>
      <material name="sensor_color"/>
    </visual>
    <collision>
      <origin
        xyz="0 0 0"
        rpy="0 0 0" />
      <geometry>
        <mesh
          filename="file://$(find peter_robot)/meshes/lidar_link.STL" />
      </geometry>
    </collision>
  </link>

  <joint name="lidar_joint"
    type="fixed">
    <origin
      xyz="-0.00184471327732116 0.000713667734151305 0.105999997"
      rpy="0 0 0" />
    <parent
      link="base_link" />
    <child
      link="lidar_link" />
    <axis
      xyz="0 0 0" />
  </joint>

  <!-- Rueda Loca -->
  <link
    name="RuedaL_link">
    <inertial>
      <origin
        xyz="-2.60208521396521E-17 -9.9370392335256E-05 0"
        rpy="0 0 0" />
      <mass
        value="0.00478152125784282" />
      <inertia
        ixx="2.26061761156593E-07"
        ixy="-3.07622501222985E-23"
        ixz="-1.66132506534916E-09"
        iyy="2.88691178201328E-07"
        iyz="2.6650338238612E-23"
        izz="2.51562599444592E-07" />
    </inertial>
    <visual>
      <origin
        xyz="0 0 0"
        rpy="0 0 0" />
      <geometry>
        <mesh
          filename="file://$(find peter_robot)/meshes/RuedaL_link.STL" />
      </geometry>
      <material
        name="sensor_color">
      </material>
    </visual>
    <collision>
      <origin
        xyz="0 0 0"
        rpy="0 0 0" />
      <geometry>
        <mesh
          filename="file://$(find peter_robot)/meshes/RuedaL_link.STL" />
      </geometry>
    </collision>
  </link>

  <joint
    name="RuedaL_joint"
    type="fixed">
    <origin
      xyz="0.000748623602797038 -0.000383625542274181 -0.0396066754484228"
      rpy="1.5707963267949 0 1.5707963267949" />
    <parent
      link="base_link" />
    <child
      link="RuedaL_link" />
    <axis
      xyz="0 0 0" />
  </joint>

  <!-- Articulacion RU -->
  <link
    name="CoxisRU_link">
    <inertial>
      <origin
        xyz="0.0274868026818202 -0.0253300526086007 -0.0260559257034611"
        rpy="0 0 0" />
      <mass
        value="0.0515846904005967" />
      <inertia
        ixx="1.75377819158699E-05"
        ixy="-6.04623186487405E-07"
        ixz="-2.40731035227905E-07"
        iyy="1.72218593142479E-05"
        iyz="3.07808211096332E-07"
        izz="8.768523256056E-06" />
    </inertial>
    <visual>
      <origin
        xyz="0 0 0"
        rpy="0 0 0" />
      <geometry>
        <mesh
          filename="file://$(find peter_robot)/meshes/CoxisRU_link.STL" />
      </geometry>
      <material
        name="coxis_color">
      </material>
    </visual>
    <collision>
      <origin
        xyz="0 0 0"
        rpy="0 0 0" />
      <geometry>
        <mesh
          filename="file://$(find peter_robot)/meshes/CoxisRU_link.STL" />
      </geometry>
    </collision>
  </link>
  <joint
    name="CoxisRU_joint"
    type="revolute">
    <origin
      xyz="0.096588488778468 -0.0607983865504415 -0.00980000000000016"
      rpy="3.14159265358979 0 -1.5707963267949" />
    <parent
      link="base_link" />
    <child
      link="CoxisRU_link" />
    <axis
      xyz="0 0 -1" />
    <limit
      lower="-1.57"
      upper="1.57"
      effort="200"
      velocity="200" />
  </joint>
  <link
    name="FemurRU_link">
    <inertial>
      <origin
        xyz="0.0427703858362092 4.6838977956095E-05 -0.00524733175036607"
        rpy="0 0 0" />
      <mass
        value="0.0322370452082158" />
      <inertia
        ixx="1.61925190691904E-05"
        ixy="1.9835660397104E-14"
        ixz="-5.08613118710115E-06"
        iyy="3.07783671522518E-05"
        iyz="-1.98360685702477E-14"
        izz="1.61925190691892E-05" />
    </inertial>
    <visual>
      <origin
        xyz="0 0 0"
        rpy="0 0 0" />
      <geometry>
        <mesh
          filename="file://$(find peter_robot)/meshes/FemurRU_link.STL" />
      </geometry>
      <material
        name="femur_color">
      </material>
    </visual>
    <collision>
      <origin
        xyz="0 0 0"
        rpy="0 0 0" />
      <geometry>
        <mesh
          filename="file://$(find peter_robot)/meshes/FemurRU_link.STL" />
      </geometry>
    </collision>
  </link>
  <joint
    name="FemurRU_joint"
    type="revolute">
    <origin
      xyz="0.0126930684475665 -0.0494626210692686 -0.0157517010851108"
      rpy="-1.57079632679489 0 0" />
    <parent
      link="CoxisRU_link" />
    <child
      link="FemurRU_link" />
    <axis
      xyz="-0.707106781186547 0 -0.707106781186548" />
    <limit
      lower="-1.57"
      upper="1.57"
      effort="200"
      velocity="200" />
  </joint>
  <link
    name="TibiaRU_link">
    <inertial>
      <origin
        xyz="0.0319359560192116 0.0193569401677476 0.0191143020997222"
        rpy="0 0 0" />
      <mass
        value="0.0667714120865957" />
      <inertia
        ixx="8.95900819681095E-06"
        ixy="8.68709912812259E-07"
        ixz="-2.03369931894634E-06"
        iyy="2.21697249659004E-05"
        iyz="-1.19329301943588E-06"
        izz="2.17599256720113E-05" />
    </inertial>
    <visual>
      <origin
        xyz="0 0 0"
        rpy="0 0 0" />
      <geometry>
        <mesh
          filename="file://$(find peter_robot)/meshes/TibiaRU_link.STL" />
      </geometry>
      <material
        name="tibia_color">
      </material>
    </visual>
    <collision>
      <origin
        xyz="0 0 0"
        rpy="0 0 0" />
      <geometry>
        <mesh
          filename="file://$(find peter_robot)/meshes/TibiaRU_link.STL" />
      </geometry>
    </collision>
  </link>
  <joint
    name="TibiaRU_joint"
    type="revolute">
    <origin
      xyz="0.0493513687238616 9.62765376531123E-05 -0.0493513687238616"
      rpy="0 0 -1.57079632679489" />
    <parent
      link="FemurRU_link" />
    <child
      link="TibiaRU_link" />
    <axis
      xyz="0 0.707106781186552 0.707106781186543" />
    <limit
      lower="-0.76"
      upper="2.38"
      effort="200"
      velocity="200" />
  </joint>
  <link
    name="RuedaRU_link">
    <inertial>
      <origin
        xyz="-0.000131053007673243 -0.000388550813708755 0.00959194646036271"
        rpy="0 0 0" />
      <mass
        value="0.041043969465447" />
      <inertia
        ixx="5.18019587347092E-06"
        ixy="2.57023939182381E-11"
        ixz="-3.07645793440467E-11"
        iyy="5.18026341245618E-06"
        iyz="-9.12119649543829E-11"
        izz="9.73025604945823E-06" />
    </inertial>
    <visual>
      <origin
        xyz="0 0 0"
        rpy="0 0 0" />
      <geometry>
        <mesh
          filename="file://$(find peter_robot)/meshes/RuedaRU_link.STL" />
      </geometry>
      <material
        name="rueda_color">
      </material>
    </visual>
    <collision>
      <origin
        xyz="0 0 0"
        rpy="0 0 0" />
      <geometry>
        <mesh
          filename="file://$(find peter_robot)/meshes/RuedaRU_link.STL" />
      </geometry>
    </collision>
  </link>
  <joint
    name="RuedaRU_joint"
    type="continuous">
    <origin
      xyz="0.109529744274998 0.0158053456421239 0.0248291866544947"
      rpy="0 1.5707963267949 0" />
    <parent
      link="TibiaRU_link" />
    <child
      link="RuedaRU_link" />
    <axis
      xyz="0 0 -1" />
  </joint>

    <!-- Bumper Sensor RU -->
  <link name="BumperRU_link">
    <inertial>
      <mass value="0.001"/>  <!-- Ajusta la masa según sea necesario -->
      <inertia ixx="0.001" iyy="0.001" izz="0.001" ixy="0" ixz="0" iyz="0"/>
    </inertial>

    <visual>
      <origin xyz="0 0 0" rpy="0 0 0"/>
      <geometry>
        <box size="0.005 0.005 0.0025"/>  <!-- Tamaño del nuevo link -->
      </geometry>
      <material name="sensor_color"/>
    </visual>

    <collision>
      <origin xyz="0 0 0" rpy="0 0 0"/>
      <geometry>
        <box size="0.02 0.02 0.01"/>  <!-- Coincide con el visual -->
      </geometry>
    </collision>
  </link>

  <joint name="BumperRU_joint" type="revolute">
    <parent link="RuedaRU_link"/>
    <child link="BumperRU_link"/>
    <origin xyz="0 0 0.03207" rpy="0 0 0"/>
    <axis xyz="0 0 1"/>
    <limit lower="0" upper="0" effort="0" velocity="0"/>
  </joint>

  <!-- Articulacion RD -->
  <link
    name="CoxisRD_link">
    <inertial>
      <origin
        xyz="0.0254334316004645 0.0274511486389335 -0.0260560368815679"
        rpy="0 0 0" />
      <mass
        value="0.0515846904005967" />
      <inertia
        ixx="1.72218580463494E-05"
        ixy="6.04623188349504E-07"
        ixz="-3.07889742191954E-07"
        iyy="1.75377831874927E-05"
        iyz="-2.40812566287735E-07"
        izz="8.76852325233184E-06" />
    </inertial>
    <visual>
      <origin
        xyz="0 0 0"
        rpy="0 0 0" />
      <geometry>
        <mesh
          filename="file://$(find peter_robot)/meshes/CoxisRD_link.STL" />
      </geometry>
      <material
        name="coxis_color">
      </material>
    </visual>
    <collision>
      <origin
        xyz="0 0 0"
        rpy="0 0 0" />
      <geometry>
        <mesh
          filename="file://$(find peter_robot)/meshes/CoxisRD_link.STL" />
      </geometry>
    </collision>
  </link>
  <joint
    name="CoxisRD_joint"
    type="revolute">
    <origin
      xyz="-0.0932301097293624 -0.0607983865504415 -0.00980000000000016"
      rpy="3.14159265358979 0 -1.5707963267949" />
    <parent
      link="base_link" />
    <child
      link="CoxisRD_link" />
    <axis
      xyz="0 0 -1" />
    <limit
      lower="-1.57"
      upper="1.57"
      effort="200"
      velocity="200" />
  </joint>
  <link
    name="FemurRD_link">
    <inertial>
      <origin
        xyz="0.00531613049563212 -6.34908792207511E-15 0.0428391845814756"
        rpy="0 0 0" />
      <mass
        value="0.0322370452082158" />
      <inertia
        ixx="1.6192519069189E-05"
        ixy="1.9836064881765E-14"
        ixz="5.08613118710121E-06"
        iyy="3.07783671522519E-05"
        iyz="1.98356572668682E-14"
        izz="1.61925190691907E-05" />
    </inertial>
    <visual>
      <origin
        xyz="0 0 0"
        rpy="0 0 0" />
      <geometry>
        <mesh
          filename="file://$(find peter_robot)/meshes/FemurRD_link.STL" />
      </geometry>
      <material
        name="femur_color">
      </material>
    </visual>
    <collision>
      <origin
        xyz="0 0 0"
        rpy="0 0 0" />
      <geometry>
        <mesh
          filename="file://$(find peter_robot)/meshes/FemurRD_link.STL" />
      </geometry>
    </collision>
  </link>
  <joint
    name="FemurRD_joint"
    type="revolute">
    <origin
      xyz="0.0495681853611769 0.0126572113832391 -0.0157518633540372"
      rpy="-1.57079632679489 0 0" />
    <parent
      link="CoxisRD_link" />
    <child
      link="FemurRD_link" />
    <axis
      xyz="0.707106781186557 0 -0.707106781186538" />
    <limit
      lower="-1.57"
      upper="1.57"
      effort="200"
      velocity="200" />
  </joint>
  <link
    name="TibiaRD_link">
    <inertial>
      <origin
        xyz="0.0319359560192096 -0.0191143020997227 0.0193569401677477"
        rpy="0 0 0" />
      <mass
        value="0.0667714120865956" />
      <inertia
        ixx="8.95900819681099E-06"
        ixy="2.03369931894647E-06"
        ixz="8.68709912812344E-07"
        iyy="2.17599256720112E-05"
        iyz="1.19329301943586E-06"
        izz="2.21697249659004E-05" />
    </inertial>
    <visual>
      <origin
        xyz="0 0 0"
        rpy="0 0 0" />
      <geometry>
        <mesh
          filename="file://$(find peter_robot)/meshes/TibiaRD_link.STL" />
      </geometry>
      <material
        name="tibia_color">
      </material>
    </visual>
    <collision>
      <origin
        xyz="0 0 0"
        rpy="0 0 0" />
      <geometry>
        <mesh
          filename="file://$(find peter_robot)/meshes/TibiaRD_link.STL" />
      </geometry>
    </collision>
  </link>
  <joint
    name="TibiaRD_joint"
    type="revolute">
    <origin
      xyz="0.049493 0 0.049493"
      rpy="0 0 -1.5708" />
    <parent
      link="FemurRD_link" />
    <child
      link="TibiaRD_link" />
    <axis
      xyz="0 -0.70711 0.70711" />
    <limit
      lower="-0.76"
      upper="2.38"
      effort="200"
      velocity="200" />
  </joint>
  <link
    name="RuedaRD_link">
    <inertial>
      <origin
        xyz="0.000388550813708921 -0.00013105300767316 0.00959194646036081"
        rpy="0 0 0" />
      <mass
        value="0.0410439694654469" />
      <inertia
        ixx="5.1802634124562E-06"
        ixy="-2.57023938999114E-11"
        ixz="9.12119649626002E-11"
        iyy="5.18019587347088E-06"
        iyz="-3.07645793582925E-11"
        izz="9.73025604945821E-06" />
    </inertial>
    <visual>
      <origin
        xyz="0 0 0"
        rpy="0 0 0" />
      <geometry>
        <mesh
          filename="file://$(find peter_robot)/meshes/RuedaRD_link.STL" />
      </geometry>
      <material
        name="rueda_color">
      </material>
    </visual>
    <collision>
      <origin
        xyz="0 0 0"
        rpy="0 0 0" />
      <geometry>
        <mesh
          filename="file://$(find peter_robot)/meshes/RuedaRD_link.STL" />
      </geometry>
    </collision>
  </link>
  <joint
    name="RuedaRD_joint"
    type="continuous">
    <origin
      xyz="0.109529744274998 -0.0248291866544958 0.0158053456421234"
      rpy="0 1.5707963267949 0" />
    <parent
      link="TibiaRD_link" />
    <child
      link="RuedaRD_link" />
    <axis
      xyz="0 0 -1" />
  </joint>

  <!-- Bumper Sensor RD -->
  <link name="BumperRD_link">
    <inertial>
      <mass value="0.001"/>  <!-- Ajusta la masa según sea necesario -->
      <inertia ixx="0.001" iyy="0.001" izz="0.001" ixy="0" ixz="0" iyz="0"/>
    </inertial>

    <visual>
      <origin xyz="0 0 0" rpy="0 0 0"/>
      <geometry>
        <box size="0.005 0.005 0.0025"/>  <!-- Tamaño del nuevo link -->
      </geometry>
      <material name="sensor_color"/>
    </visual>

    <collision>
      <origin xyz="0 0 0" rpy="0 0 0"/>
      <geometry>
        <box size="0.02 0.02 0.01"/>  <!-- Coincide con el visual -->
      </geometry>
    </collision>
  </link>

  <joint name="BumperRD_joint" type="revolute">
    <parent link="RuedaRD_link"/>
    <child link="BumperRD_link"/>
    <origin xyz= "0 0 0.03207" rpy="0 0 0"/>
    <axis xyz="0 0 1"/>
    <limit lower="0" upper="0" effort="0" velocity="0"/>
  </joint>

  <!-- Articulacion LU -->
  <link
    name="CoxisLU_link">
    <inertial>
      <origin
        xyz="0.0273534619284208 0.0254747642770079 -0.0260560409410945"
        rpy="0 0 0" />
      <mass
        value="0.0515847008737884" />
      <inertia
        ixx="1.75378033236604E-05"
        ixy="6.04620201049237E-07"
        ixz="-2.40808419843913E-07"
        iyy="1.72218513968338E-05"
        iyz="-3.078997409612E-07"
        izz="8.76852925706835E-06" />
    </inertial>
    <visual>
      <origin
        xyz="0 0 0"
        rpy="0 0 0" />
      <geometry>
        <mesh
          filename="file://$(find peter_robot)/meshes/CoxisLU_link.STL" />
      </geometry>
      <material
        name="coxis_color">
      </material>
    </visual>
    <collision>
      <origin
        xyz="0 0 0"
        rpy="0 0 0" />
      <geometry>
        <mesh
          filename="file://$(find peter_robot)/meshes/CoxisLU_link.STL" />
      </geometry>
    </collision>
  </link>
  <joint
    name="CoxisLU_joint"
    type="revolute">
    <origin
      xyz="0.0965884887784687 0.060798386550441 -0.00979999999999995"
      rpy="-3.14159265358979 0 1.5707963267949" />
    <parent
      link="base_link" />
    <child
      link="CoxisLU_link" />
    <axis
      xyz="0 0 -1" />
    <limit
      lower="-1.57"
      upper="1.57"
      effort="200"
      velocity="200" />
  </joint>
  <link
    name="FemurLU_link">
    <inertial>
      <origin
        xyz="0.0428391845814535 1.70002900645727E-14 0.00531613049560975"
        rpy="0 0 0" />
      <mass
        value="0.0322370452082159" />
      <inertia
        ixx="1.61925190691903E-05"
        ixy="-1.983234495467E-14"
        ixz="5.08613118710213E-06"
        iyy="3.077836715225E-05"
        iyz="-1.98330684644081E-14"
        izz="1.61925190691913E-05" />
    </inertial>
    <visual>
      <origin
        xyz="0 0 0"
        rpy="0 0 0" />
      <geometry>
        <mesh
          filename="file://$(find peter_robot)/meshes/FemurLU_link.STL" />
      </geometry>
      <material
        name="femur_color">
      </material>
    </visual>
    <collision>
      <origin
        xyz="0 0 0"
        rpy="0 0 0" />
      <geometry>
        <mesh
          filename="file://$(find peter_robot)/meshes/FemurLU_link.STL" />
      </geometry>
    </collision>
  </link>
  <joint
    name="FemurLU_joint"
    type="revolute">
    <origin
      xyz="0.0125512915293921 0.0496036868635676 -0.0157518633540368"
      rpy="-1.5707963267949 0 0" />
    <parent
      link="CoxisLU_link" />
    <child
      link="FemurLU_link" />
    <axis
      xyz="-0.707106781186545 0 0.70710678118655" />
    <limit
      lower="-1.57"
      upper="1.57"
      effort="200"
      velocity="200" />
  </joint>
  <link
    name="TibiaLU_link">
    <inertial>
      <origin
        xyz="0.0318333709154974 0.0193548449337303 -0.0191311326900838"
        rpy="0 0 0" />
      <mass
        value="0.066747630746101" />
      <inertia
        ixx="8.98829368251505E-06"
        ixy="9.89450755030482E-07"
        ixz="2.02354751919822E-06"
        iyy="2.2512850793934E-05"
        iyz="1.20714490535372E-06"
        izz="2.20842158995089E-05" />
    </inertial>
    <visual>
      <origin
        xyz="0 0 0"
        rpy="0 0 0" />
      <geometry>
        <mesh
          filename="file://$(find peter_robot)/meshes/TibiaLU_link.STL" />
      </geometry>
      <material
        name="tibia_color">
      </material>
    </visual>
    <collision>
      <origin
        xyz="0 0 0"
        rpy="0 0 0" />
      <geometry>
        <mesh
          filename="file://$(find peter_robot)/meshes/TibiaLU_link.STL" />
      </geometry>
    </collision>
  </link>
  <joint
    name="TibiaLU_joint"
    type="revolute">
    <origin
      xyz="0.049493 0 0.049493"
      rpy="0 0 -1.5708" />
    <parent
      link="FemurLU_link" />
    <child
      link="TibiaLU_link" />
    <axis
      xyz="0 0.70711 -0.70711" />
    <limit
      lower="-2.38"
      upper="0.76"
      effort="200"
      velocity="200" />
  </joint>
  <link
    name="RuedaLU_link">
    <inertial>
      <origin
        xyz="0.000388550813709809 -0.000131053007687745 0.00959201746706932"
        rpy="0 0 0" />
      <mass
        value="0.0410439694650791" />
      <inertia
        ixx="5.18026340751663E-06"
        ixy="-2.57018167887053E-11"
        ixz="9.12119649306578E-11"
        iyy="5.18019587834666E-06"
        iyz="-3.07645793546219E-11"
        izz="9.73025604949043E-06" />
    </inertial>
    <visual>
      <origin
        xyz="0 0 0"
        rpy="0 0 0" />
      <geometry>
        <mesh
          filename="file://$(find peter_robot)/meshes/RuedaLU_link.STL" />
      </geometry>
      <material
        name="rueda_color">
      </material>
    </visual>
    <collision>
      <origin
        xyz="0 0 0"
        rpy="0 0 0" />
      <geometry>
        <mesh
          filename="file://$(find peter_robot)/meshes/RuedaLU_link.STL" />
      </geometry>
    </collision>
  </link>
  <joint
    name="RuedaLU_joint"
    type="continuous">
    <origin
      xyz="0.10953 0.016128 -0.025208"
      rpy="0 1.5708 0" />
    <parent
      link="TibiaLU_link" />
    <child
      link="RuedaLU_link" />
    <axis
      xyz="0 0 -1" />
  </joint>

  <!-- Bumper Sensor LU -->
  <link name="BumperLU_link">
    <inertial>
      <mass value="0.001"/>  <!-- Ajusta la masa según sea necesario -->
      <inertia ixx="0.001" iyy="0.001" izz="0.001" ixy="0" ixz="0" iyz="0"/>
    </inertial>

    <visual>
      <origin xyz="0 0 0" rpy="0 0 0"/>
      <geometry>
        <box size="0.005 0.005 0.0025"/>  <!-- Tamaño del nuevo link -->
      </geometry>
      <material name="sensor_color"/>
    </visual>

    <collision>
      <origin xyz="0 0 0" rpy="0 0 0"/>
      <geometry>
        <box size="0.02 0.02 0.01"/>  <!-- Coincide con el visual -->
      </geometry>
    </collision>
  </link>

  <joint name="BumperLU_joint" type="revolute">
    <parent link="RuedaLU_link"/>
    <child link="BumperLU_link"/>
    <origin xyz= "0 0 0.03207" rpy="0 0 0"/>
    <axis xyz="0 0 1"/>
    <limit lower="0" upper="0" effort="0" velocity="0"/>
  </joint>

  <!-- Articulacion LD -->
  <link
    name="CoxisLD_link">
    <inertial>
      <origin
        xyz="0.0254391147078342 -0.0274568453944841 -0.0260559294832483"
        rpy="0 0 0" />
      <mass
        value="0.0515847008737883" />
      <inertia
        ixx="1.72218526647141E-05"
        ixy="-6.04620199168892E-07"
        ixz="-3.07818209872126E-07"
        iyy="1.75378020520194E-05"
        iyz="2.40726888777337E-07"
        izz="8.76852926082903E-06" />
    </inertial>
    <visual>
      <origin
        xyz="0 0 0"
        rpy="0 0 0" />
      <geometry>
        <mesh
          filename="file://$(find peter_robot)/meshes/CoxisLD_link.STL" />
      </geometry>
      <material
        name="coxis_color">
      </material>
    </visual>
    <collision>
      <origin
        xyz="0 0 0"
        rpy="0 0 0" />
      <geometry>
        <mesh
          filename="file://$(find peter_robot)/meshes/CoxisLD_link.STL" />
      </geometry>
    </collision>
  </link>
  <joint
    name="CoxisLD_joint"
    type="revolute">
    <origin
      xyz="-0.09323 0.060798 -0.0098"
      rpy="-3.1416 0 1.5708" />
    <parent
      link="base_link" />
    <child
      link="CoxisLD_link" />
    <axis
      xyz="0 0 -1" />
    <limit
      lower="-1.57"
      upper="1.57"
      effort="200"
      velocity="200" />
  </joint>
  <link
    name="FemurLD_link">
    <inertial>
      <origin
        xyz="0.00531617732277645 -3.24549499681331E-07 -0.0428392314086188"
        rpy="0 0 0" />
      <mass
        value="0.0322370452082158" />
      <inertia
        ixx="1.61925190691904E-05"
        ixy="-1.98356748400012E-14"
        ixz="-5.08613118710121E-06"
        iyy="3.07783671522519E-05"
        iyz="1.98360420605306E-14"
        izz="1.61925190691893E-05" />
    </inertial>
    <visual>
      <origin
        xyz="0 0 0"
        rpy="0 0 0" />
      <geometry>
        <mesh
          filename="file://$(find peter_robot)/meshes/FemurLD_link.STL" />
      </geometry>
      <material
        name="femur_color">
      </material>
    </visual>
    <collision>
      <origin
        xyz="0 0 0"
        rpy="0 0 0" />
      <geometry>
        <mesh
          filename="file://$(find peter_robot)/meshes/FemurLD_link.STL" />
      </geometry>
    </collision>
  </link>
  <joint
    name="FemurLD_joint"
    type="revolute">
    <origin
      xyz="0.049567 -0.012656 -0.015752"
      rpy="-1.5708 0 0" />
    <parent
      link="CoxisLD_link" />
    <child
      link="FemurLD_link" />
    <axis
      xyz="0.70711 0 0.70711" />
    <limit
      lower="-1.57"
      upper="1.57"
      effort="200"
      velocity="200" />
  </joint>
  <link
    name="TibiaLD_link">
    <inertial>
      <origin
        xyz="0.0318336954649925 -0.019131085862914 -0.0193548917608989"
        rpy="0 0 0" />
      <mass
        value="0.0667476307461011" />
      <inertia
        ixx="8.98829368251505E-06"
        ixy="2.02354751919823E-06"
        ixz="-9.89450755030507E-07"
        iyy="2.2084215899509E-05"
        iyz="-1.20714490535371E-06"
        izz="2.25128507939341E-05" />
    </inertial>
    <visual>
      <origin
        xyz="0 0 0"
        rpy="0 0 0" />
      <geometry>
        <mesh
          filename="file://$(find peter_robot)/meshes/TibiaLD_link.STL" />
      </geometry>
      <material
        name="tibia_color">
      </material>
    </visual>
    <collision>
      <origin
        xyz="0 0 0"
        rpy="0 0 0" />
      <geometry>
        <mesh
          filename="file://$(find peter_robot)/meshes/TibiaLD_link.STL" />
      </geometry>
    </collision>
  </link>
  <joint
    name="TibiaLD_joint"
    type="revolute">
    <origin
      xyz="0.049493 0 -0.049493"
      rpy="0 0 -1.5708" />
    <parent
      link="FemurLD_link" />
    <child
      link="TibiaLD_link" />
    <axis
      xyz="0 -0.70711 -0.70711" />
    <limit
      lower="-2.38"
      upper="0.76"
      effort="200"
      velocity="200" />
  </joint>
  <link
    name="RuedaLD_link">
    <inertial>
      <origin
        xyz="-0.000131053007687898 -0.000388550813709865 0.00959201746707292"
        rpy="0 0 0" />
      <mass
        value="0.041043969465079" />
      <inertia
        ixx="5.18019587834664E-06"
        ixy="2.57018167692184E-11"
        ixz="-3.07645793605211E-11"
        iyy="5.18026340751662E-06"
        iyz="-9.12119649536465E-11"
        izz="9.73025604949041E-06" />
    </inertial>
    <visual>
      <origin
        xyz="0 0 0"
        rpy="0 0 0" />
      <geometry>
        <mesh
          filename="file://$(find peter_robot)/meshes/RuedaLD_link.STL" />
      </geometry>
      <material
        name="rueda_color">
      </material>
    </visual>
    <collision>
      <origin
        xyz="0 0 0"
        rpy="0 0 0" />
      <geometry>
        <mesh
          filename="file://$(find peter_robot)/meshes/RuedaLD_link.STL" />
      </geometry>
    </collision>
  </link>
  <joint
    name="RuedaLD_joint"
    type="continuous">
    <origin
      xyz="0.109530068824489 -0.0252082867118495 -0.0161284884758471"
      rpy="0 1.5707963267949 0" />
    <parent
      link="TibiaLD_link" />
    <child
      link="RuedaLD_link" />
    <axis
      xyz="0 0 -1" />
  </joint>

  <!-- Bumper Sensor LD -->
  <link name="BumperLD_link">
    <inertial>
      <mass value="0.001"/>  <!-- Ajusta la masa según sea necesario -->
      <inertia ixx="0.001" iyy="0.001" izz="0.001" ixy="0" ixz="0" iyz="0"/>
    </inertial>

    <visual>
      <origin xyz="0 0 0" rpy="0 0 0"/>
      <geometry>
        <box size="0.005 0.005 0.0025"/>  <!-- Tamaño del nuevo link -->
      </geometry>
      <material name="sensor_color"/>
    </visual>

    <collision>
      <origin xyz="0 0 0" rpy="0 0 0"/>
      <geometry>
        <box size="0.02 0.02 0.01"/>  <!-- Coincide con el visual -->
      </geometry>
    </collision>
  </link>

  <joint name="BumperLD_joint" type="revolute">
    <parent link="RuedaLD_link"/>
    <child link="BumperLD_link"/>
    <origin xyz= "0 0 0.03207" rpy="0 0 0"/>
    <axis xyz="0 0 1"/>
    <limit lower="0" upper="0" effort="0" velocity="0"/>
  </joint>

  <!-- HEAD -->
  <link
    name="Head_z_link">
    <inertial>
      <origin
        xyz="0.00116172788742119 -0.00555966962190932 0.00797693292542438"
        rpy="0 0 0" />
      <mass
        value="0.0103184370744868" />
      <inertia
        ixx="5.93065414360317E-07"
        ixy="-3.6867328759808E-08"
        ixz="-4.45440875471918E-10"
        iyy="7.92428007376184E-07"
        iyz="-1.31379509022269E-08"
        izz="1.14580887737191E-06" />
    </inertial>
    <visual>
      <origin
        xyz="0 0 0"
        rpy="0 0 0" />
      <geometry>
        <mesh
          filename="file://$(find peter_robot)/meshes/Head_z_link.STL" />
      </geometry>
      <material
        name="headz_color">
      </material>
    </visual>
    <collision>
      <origin
        xyz="0 0 0"
        rpy="0 0 0" />
      <geometry>
        <mesh
          filename="file://$(find peter_robot)/meshes/Head_z_link.STL" />
      </geometry>
    </collision>
  </link>

  <joint name="Head_z_joint"
    type="revolute">
    <origin
      xyz="0.077725 0.0055 0.0205"
      rpy="0 0 0" />
    <parent
      link="base_link" />
    <child
      link="Head_z_link" />
    <axis
      xyz="0 0 1" />
    <limit
      lower="-1.57"
      upper="1.57"
      effort="200"
      velocity="200" />
  </joint>

  <link name="Head_y_link">
    <inertial>
      <origin
        xyz="0.0284221619805605 -0.0189346308341868 0.0132736474965603"
        rpy="0 0 0" />
      <mass
        value="0.0163382220637024" />
      <inertia
        ixx="5.1822549216056E-06"
        ixy="3.79870864042615E-07"
        ixz="5.64157454343844E-08"
        iyy="2.78198230437846E-06"
        iyz="1.85983561503811E-07"
        izz="3.70745019487904E-06" />
    </inertial>
    <visual>
      <origin
        xyz="0 0 0"
        rpy="0 0 0" />
      <geometry>
        <mesh
          filename="file://$(find peter_robot)/meshes/Head_y_link.STL" />
      </geometry>
      <material name="heady_color"/>
    </visual>
    <collision>
      <origin
        xyz="0 0 0"
        rpy="0 0 0" />
      <geometry>
        <mesh
          filename="file://$(find peter_robot)/meshes/Head_y_link.STL" />
      </geometry>
    </collision>
  </link>

  <joint name="Head_y_joint"
    type="revolute">
    <origin
      xyz="0.00629999999999953 0.0128 0.00994999999999965"
      rpy="0 0 0" />
    <parent
      link="Head_z_link" />
    <child
      link="Head_y_link" />
    <axis
      xyz="0 -1 0" />
    <limit
      lower="-1.57"
      upper="1.57"
      effort="200"
      velocity="200" />
  </joint>

</robot>