<?xml version="1.0" encoding="utf-8"?>
<!-- This URDF was automatically created by SolidWorks to URDF Exporter! Originally created by Stephen Brawner (brawner@gmail.com) 
     Commit Version: 1.6.0-4-g7f85cfe  Build Version: 1.6.7995.38578
     For more information, please see http://wiki.ros.org/sw_urdf_exporter -->
<robot
  name="peter_robot">
  <link
    name="base_link">
    <inertial>
      <origin
        xyz="0.0057951163939445818 0.0094736464900437718 0.02"
        rpy="0 0 0" />
      <mass
        value="3.0" />
      <inertia
        ixx="0.000954916141298042"
        ixy="-0.000122009140351572"
        ixz="0.00049717087497589"
        iyy="0.000938276141298042"
        iyz="-0.000196141248736565"
        izz="0.000187141337876107" />
    </inertial>
    <visual>
      <origin
        xyz="0 0 0"
        rpy="0 0 0" />
      <geometry>
        <mesh
          filename="package://peter_robot/meshes/Cuerpo_link.STL" />
      </geometry>
      <material
        name="">
        <color
          rgba="0.792156862745098 0.819607843137255 0.933333333333333 1" />
      </material>
    </visual>
    <collision>
      <origin
        xyz="0 0 0"
        rpy="0 0 0" />
      <geometry>
        <mesh
          filename="package://peter_robot/meshes/Cuerpo_link.STL" />
      </geometry>
    </collision>
  </link>

  <link name="imu_link">
    <visual>
      <geometry>
        <box size="0.02 0.02 0.01"/>
      </geometry>
    </visual>
    <collision>
      <geometry>
        <box size="0.1 0.1 0.05"/>
      </geometry>
    </collision>
    <inertial>
      <mass value="1e-5" />
      <origin xyz="0 0 0" rpy="0 0 0"/>
      <inertia ixx="1e-6" ixy="0" ixz="0" iyy="1e-6" iyz="0" izz="1e-6" />
    </inertial>
  </link>

  <joint
    name="IMU_joint"
    type="fixed">
    <origin
      xyz="0.0 0.0 0.005"
      rpy="3.1416 0 -1.5708" />
    <parent
      link="base_link" />
    <child
      link="imu_link" />
    <axis
      xyz="0 0 -1" />
  </joint>

  <gazebo reference="imu_link">
    <gravity>true</gravity>
    <sensor name="imu_sensor" type="imu">
      <always_on>true</always_on>
      <update_rate>100</update_rate>
      <visualize>true</visualize>
      <topic>__default_topic__</topic>
      <plugin filename="libgazebo_ros_imu_sensor.so" name="imu_plugin">
        <topicName>imu</topicName>
        <bodyName>imu_link</bodyName>
        <updateRateHZ>10.0</updateRateHZ>
        <gaussianNoise>0.0</gaussianNoise>
        <xyzOffset>0 0 0</xyzOffset>
        <rpyOffset>0 0 0</rpyOffset>
        <frameName>imu_link</frameName>
      </plugin>
      <pose>0 0 0 0 0 0</pose>
    </sensor>
  </gazebo>

  <link
    name="CoxisRU_link">
    <inertial>
      <origin
        xyz="0.0145758033903628 -0.000148324192035865 -0.00157951128660489"
        rpy="0 0 0" />
      <mass
        value="0.0198300229745734" />
      <inertia
        ixx="0.00033203887322426106"
        ixy="0.0074374349937085608"
        ixz="0.0056481319330245408"
        iyy="0.0046818529679331306"
        iyz="-0.0059763363601787710"
        izz="0.0062779650870579606" />
    </inertial>
    <visual>
      <origin
        xyz="0 0 0"
        rpy="0 0 0" />
      <geometry>
        <mesh
          filename="package://peter_robot/meshes/CoxisRU_link.STL" />
      </geometry>
      <material
        name="">
        <color
          rgba="0.792156862745098 0.819607843137255 0.933333333333333 1" />
      </material>
    </visual>
    <collision>
      <origin
        xyz="0 0 0"
        rpy="0 0 0" />
      <geometry>
        <mesh
          filename="package://peter_robot/meshes/CoxisRU_link.STL" />
      </geometry>
    </collision>
  </link>
  <joint
    name="CoxisRU_joint"
    type="revolute">
    <origin
      xyz="0.0558 -0.0558 0.02"
      rpy="3.1416 0 -1.5708" />
    <parent
      link="base_link" />
    <child
      link="CoxisRU_link" />
    <axis
      xyz="0 0 -1" />
    <limit
      lower="0"
      upper="1.57"
      effort="300"
      velocity="3" />
  </joint>
  <link
    name="FemurRU_link">
    <inertial>
      <origin
        xyz="0.0158446271127422 0.000731589545819266 -0.00234896627561063"
        rpy="0 0 0" />
      <mass
        value="0.0267646481312129" />
      <inertia
        ixx="0.0027372725885784506"
        ixy="0.0031908239997210907"
        ixz="0.0085342307337404507"
        iyy="0.0073568709647354206"
        iyz="-0.0032602627250091908"
        izz="0.0075404497968736806" />
    </inertial>
    <visual>
      <origin
        xyz="0 0 0"
        rpy="0 0 0" />
      <geometry>
        <mesh
          filename="package://peter_robot/meshes/FemurRU_link.STL" />
      </geometry>
      <material
        name="">
        <color
          rgba="1 1 1 1" />
      </material>
    </visual>
    <collision>
      <origin
        xyz="0 0 0"
        rpy="0 0 0" />
      <geometry>
        <mesh
          filename="package://peter_robot/meshes/FemurRU_link.STL" />
      </geometry>
    </collision>
  </link>
  <joint
    name="FemurRU_joint"
    type="revolute">
    <origin
      xyz="0.04455 0 -0.0046"
      rpy="-1.5708 0 0" />
    <parent
      link="CoxisRU_link" />
    <child
      link="FemurRU_link" />
    <axis
      xyz="0 0 -1" />
    <limit
      lower="-0.785"
      upper="0.785"
      effort="300"
      velocity="3" />
  </joint>
  <link
    name="TibiaRU_link">
    <inertial>
      <origin
        xyz="0.0303344390438305 -0.0064645402920726606 -0.00266255588885558"
        rpy="0 0 0" />
      <mass
        value="0.0203567389256734" />
      <inertia
        ixx="0.001075309559184606"
        ixy="0.0040821313346320112"
        ixz="-0.0072023647371747208"
        iyy="0.0035902033061377306"
        iyz="0.0080605163458934112"
        izz="0.0037227584809434606" />
    </inertial>
    <visual>
      <origin
        xyz="0 0 0"
        rpy="0 0 0" />
      <geometry>
        <mesh
          filename="package://peter_robot/meshes/TibiaRU_link.STL" />
      </geometry>
      <material
        name="">
        <color
          rgba="0.792156862745098 0.819607843137255 0.933333333333333 1" />
      </material>
    </visual>
    <collision>
      <origin
        xyz="0 0 0"
        rpy="0 0 0" />
      <geometry>
        <mesh
          filename="package://peter_robot/meshes/TibiaRU_link.STL" />
      </geometry>
    </collision>
  </link>
  <joint
    name="TibiaRU_joint"
    type="revolute">
    <origin
      xyz="0.05395 0 0.0016"
      rpy="0 0 -1.5708" />
    <parent
      link="FemurRU_link" />
    <child
      link="TibiaRU_link" />
    <axis
      xyz="0 0 -1" />
    <limit
      lower="-1.57"
      upper="0.3925"
      effort="300"
      velocity="3" />
  </joint>


<!--   BUMPER SENSOR
  <link name="TibiaRU_Bump_link">
    <visual>
      <geometry>
        <box size="0.06 0.06 0.06"/> // Deje un tamaño exagerado para probar las colisiones de manera más fácil. Aún así no funcionó.
      </geometry>
    </visual>
    <collision>
      <geometry>
        <box size="0.06 0.06 0.06"/>
      </geometry>
    </collision>
    <inertial>
      <mass value="1e-5" />
      <origin xyz="0 0 -0.02" rpy="0 0 0"/>
      <inertia ixx="1e-6" ixy="0" ixz="0" iyy="1e-6" iyz="0" izz="1e-6" />
    </inertial>
  </link>

  <joint
    name="TibiaRU_Bump_joint"
    type="fixed">
    <origin
      xyz="0.0 0.0 -0.5" // Si se quiere volver a intentar cuadrar mejor eje z (valor actual -0.5)
      rpy="3.1416 0 -1.5708" />
    <parent
      link="TibiaRU_link" />
    <child
      link="TibiaRU_Bump_link" />
    <axis
      xyz="0 0 -1" />
  </joint>

  <gazebo reference="TibiaRU_Bump_link">
    <selfCollide>true</selfCollide>
    <sensor name= "TibiaRU_bumper" type="contact">
        <alwaysOn>true</alwaysOn>
        <updateRate>15.0</updateRate>
        <plugin name="gazebo_ros_bumper_controller" filename="libgazebo_ros_bumper.so">   
            <bumperTopicName>bumper_TibiaRU</bumperTopicName>
            <contact>
              <collision>TibiaRU_link_fixed_joint_lump__TibiaRU_Bump_link_collision_1</collision>
            </contact>
            <frameName>world</frameName>
        </plugin>
    </sensor>
  </gazebo> -->

  <link
    name="RuedaRU_link">
    <inertial>
      <origin
        xyz="-0.0022780147213019610 0.0025475066500746410 -0.0063190357210696208"
        rpy="0 0 0" />
      <mass
        value="0.0405034383813953" />
      <inertia
        ixx="0.005174137497296206"
        ixy="0.0068457155389386413"
        ixz="0.0021378186017250514"
        iyy="0.0051741383388720806"
        iyz="0.0066069139604846515"
        izz="0.0097299113209887706" />
    </inertial>
    <visual>
      <origin
        xyz="0 0 0"
        rpy="0 0 0" />
      <geometry>
        <mesh
          filename="package://peter_robot/meshes/RuedaRU_link.STL" />
      </geometry>
      <material
        name="">
        <color
          rgba="0.792156862745098 0.819607843137255 0.933333333333333 1" />
      </material>
    </visual>
    <collision>
      <origin
        xyz="0 0 0"
        rpy="0 0 0" />
      <geometry>
        <mesh
          filename="package://peter_robot/meshes/RuedaRU_link.STL" />
      </geometry>
    </collision>
  </link>
  <joint
    name="RuedaRU_joint"
    type="continuous">
    <origin
      xyz="0.07225 0 -0.0039"
      rpy="0 1.5708 0" />
    <parent
      link="TibiaRU_link" />
    <child
      link="RuedaRU_link" />
    <axis
      xyz="0 0 -1" />
    <limit
      effort="300"
      velocity="3" />
  </joint>
  <link
    name="CoxisLU_link">
    <inertial>
      <origin
        xyz="0.0145758033898372 -0.000148324188575952 -0.00157951128572802"
        rpy="0 0 0" />
      <mass
        value="0.0198300229757828" />
      <inertia
        ixx="0.0033203887324183906"
        ixy="0.0074374350512450708"
        ixz="0.0056481319356737508"
        iyy="0.0046818529679575306"
        iyz="-0.0059763413290627210"
        izz="0.0062779650870379706" />
    </inertial>
    <visual>
      <origin
        xyz="0 0 0"
        rpy="0 0 0" />
      <geometry>
        <mesh
          filename="package://peter_robot/meshes/CoxisLU_link.STL" />
      </geometry>
      <material
        name="">
        <color
          rgba="0.792156862745098 0.819607843137255 0.933333333333333 1" />
      </material>
    </visual>
    <collision>
      <origin
        xyz="0 0 0"
        rpy="0 0 0" />
      <geometry>
        <mesh
          filename="package://peter_robot/meshes/CoxisLU_link.STL" />
      </geometry>
    </collision>
  </link>
  <joint
    name="CoxisLU_joint"
    type="revolute">
    <origin
      xyz="0.0558 0.0558 0.02"
      rpy="3.1416 0 1.5708" />
    <parent
      link="base_link" />
    <child
      link="CoxisLU_link" />
    <axis
      xyz="0 0 -1" />
    <limit
      lower="-1.57"
      upper="0"
      effort="300"
      velocity="3" />
  </joint>
  <link
    name="FemurLU_link">
    <inertial>
      <origin
        xyz="0.0158446270939323 0.000731589541232057 -0.0023489662634897"
        rpy="0 0 0" />
      <mass
        value="0.0267646481619211" />
      <inertia
        ixx="0.0027372725904361806"
        ixy="0.0031908239941182507"
        ixz="0.0085342307466234407"
        iyy="0.0073568709674539306"
        iyz="-0.003260262652798508"
        izz="0.0075404497985481606" />
    </inertial>
    <visual>
      <origin
        xyz="0 0 0"
        rpy="0 0 0" />
      <geometry>
        <mesh
          filename="package://peter_robot/meshes/FemurLU_link.STL" />
      </geometry>
      <material
        name="">
        <color
          rgba="1 1 1 1" />
      </material>
    </visual>
    <collision>
      <origin
        xyz="0 0 0"
        rpy="0 0 0" />
      <geometry>
        <mesh
          filename="package://peter_robot/meshes/FemurLU_link.STL" />
      </geometry>
    </collision>
  </link>
  <joint
    name="FemurLU_joint"
    type="revolute">
    <origin
      xyz="0.04455 0 -0.0046"
      rpy="-1.5708 0 0" />
    <parent
      link="CoxisLU_link" />
    <child
      link="FemurLU_link" />
    <axis
      xyz="0 0 -1" />
    <limit
      lower="-0.785"
      upper="0.785"
      effort="300"
      velocity="3" />
  </joint>
  <link
    name="TibiaLU_link">
    <inertial>
      <origin
        xyz="0.0303344390398229 -0.0064645402714225106 0.000537444112589075"
        rpy="0 0 0" />
      <mass
        value="0.0203567389283255" />
      <inertia
        ixx="0.0010753095594363206"
        ixy="0.0040821340532090512"
        ixz="-0.0072023647216624708"
        iyy="0.0035902033064178606"
        iyz="0.0080605028999537812"
        izz="0.0037227584810593206" />
    </inertial>
    <visual>
      <origin
        xyz="0 0 0"
        rpy="0 0 0" />
      <geometry>
        <mesh
          filename="package://peter_robot/meshes/TibiaLU_link.STL" />
      </geometry>
      <material
        name="">
        <color
          rgba="0.792156862745098 0.819607843137255 0.933333333333333 1" />
      </material>
    </visual>
    <collision>
      <origin
        xyz="0 0 0"
        rpy="0 0 0" />
      <geometry>
        <mesh
          filename="package://peter_robot/meshes/TibiaLU_link.STL" />
      </geometry>
    </collision>
  </link>
  <joint
    name="TibiaLU_joint"
    type="revolute">
    <origin
      xyz="0.05395 0 -0.0016"
      rpy="0 0 -1.5708" />
    <parent
      link="FemurLU_link" />
    <child
      link="TibiaLU_link" />
    <axis
      xyz="0 0 -1" />
    <limit
      lower="-1.57"
      upper="0.3925"
      effort="300"
      velocity="3" />
  </joint>
  <link
    name="RuedaLU_link">
    <inertial>
      <origin
        xyz="0.002278017288692710 -0.0025475083154091710 -0.0063190355295561508"
        rpy="0 0 0" />
      <mass
        value="0.0405034383813952" />
      <inertia
        ixx="0.005174137497296206"
        ixy="0.0068457155759549713"
        ixz="-0.0021378184629713714"
        iyy="0.0051741383388720806"
        iyz="-0.0066069135756848315"
        izz="0.0097299113209887706" />
    </inertial>
    <visual>
      <origin
        xyz="0 0 0"
        rpy="0 0 0" />
      <geometry>
        <mesh
          filename="package://peter_robot/meshes/RuedaLU_link.STL" />
      </geometry>
      <material
        name="">
        <color
          rgba="0.792156862745098 0.819607843137255 0.933333333333333 1" />
      </material>
    </visual>
    <collision>
      <origin
        xyz="0 0 0"
        rpy="0 0 0" />
      <geometry>
        <mesh
          filename="package://peter_robot/meshes/RuedaLU_link.STL" />
      </geometry>
    </collision>
  </link>
  <joint
    name="RuedaLU_joint"
    type="continuous">
    <origin
      xyz="0.07225 0 -0.0007"
      rpy="0 -1.5708 0" />
    <parent
      link="TibiaLU_link" />
    <child
      link="RuedaLU_link" />
    <axis
      xyz="0 0 -1" />
  </joint>
  <link
    name="CoxisRD_link">
    <inertial>
      <origin
        xyz="0.0145758034147555 -0.000148324186287456 -0.00157951130233852"
        rpy="0 0 0" />
      <mass
        value="0.0198300229471255" />
      <inertia
        ixx="0.0033203887309334506"
        ixy="0.0074374350931830508"
        ixz="0.0056481317661782108"
        iyy="0.0046818529645321506"
        iyz="-0.0059763449243910710"
        izz="0.0062779650849971806" />
    </inertial>
    <visual>
      <origin
        xyz="0 0 0"
        rpy="0 0 0" />
      <geometry>
        <mesh
          filename="package://peter_robot/meshes/CoxisRD_link.STL" />
      </geometry>
      <material
        name="">
        <color
          rgba="0.792156862745098 0.819607843137255 0.933333333333333 1" />
      </material>
    </visual>
    <collision>
      <origin
        xyz="0 0 0"
        rpy="0 0 0" />
      <geometry>
        <mesh
          filename="package://peter_robot/meshes/CoxisRD_link.STL" />
      </geometry>
    </collision>
  </link>
  <joint
    name="CoxisRD_joint"
    type="revolute">
    <origin
      xyz="-0.0558 -0.0558 0.02"
      rpy="3.1416 0 -1.5708" />
    <parent
      link="base_link" />
    <child
      link="CoxisRD_link" />
    <axis
      xyz="0 0 -1" />
    <limit
      lower="-1.57"
      upper="0"
      effort="300"
      velocity="3" />
  </joint>
  <link
    name="FemurRD_link">
    <inertial>
      <origin
        xyz="0.0158446271061813 0.000731589545244282 -0.00234896627188297"
        rpy="0 0 0" />
      <mass
        value="0.0267646481407517" />
      <inertia
        ixx="0.0027372725890429706"
        ixy="0.0031908239989177907"
        ixz="0.0085342307390399407"
        iyy="0.0073568709658379206"
        iyz="-0.0032602627185682608"
        izz="0.0075404497975679406" />
    </inertial>
    <visual>
      <origin
        xyz="0 0 0"
        rpy="0 0 0" />
      <geometry>
        <mesh
          filename="package://peter_robot/meshes/FemurRD_link.STL" />
      </geometry>
      <material
        name="">
        <color
          rgba="1 1 1 1" />
      </material>
    </visual>
    <collision>
      <origin
        xyz="0 0 0"
        rpy="0 0 0" />
      <geometry>
        <mesh
          filename="package://peter_robot/meshes/FemurRD_link.STL" />
      </geometry>
    </collision>
  </link>
  <joint
    name="FemurRD_joint"
    type="revolute">
    <origin
      xyz="0.04455 0 -0.0046"
      rpy="-1.5708 0 0" />
    <parent
      link="CoxisRD_link" />
    <child
      link="FemurRD_link" />
    <axis
      xyz="0 0 -1" />
    <limit
      lower="-0.785"
      upper="0.785"
      effort="300"
      velocity="3" />
  </joint>
  <link
    name="TibiaRD_link">
    <inertial>
      <origin
        xyz="0.0303344391647721 -0.0064645363408999406 -0.0026625559205628"
        rpy="0 0 0" />
      <mass
        value="0.0203567388517281" />
      <inertia
        ixx="0.0010753095557645506"
        ixy="0.0040828428449131212"
        ixz="-0.0072023651659255508"
        iyy="0.0035902032972577406"
        iyz="0.008059946090131212"
        izz="0.0037227584753179706" />
    </inertial>
    <visual>
      <origin
        xyz="0 0 0"
        rpy="0 0 0" />
      <geometry>
        <mesh
          filename="package://peter_robot/meshes/TibiaRD_link.STL" />
      </geometry>
      <material
        name="">
        <color
          rgba="0.792156862745098 0.819607843137255 0.933333333333333 1" />
      </material>
    </visual>
    <collision>
      <origin
        xyz="0 0 0"
        rpy="0 0 0" />
      <geometry>
        <mesh
          filename="package://peter_robot/meshes/TibiaRD_link.STL" />
      </geometry>
    </collision>
  </link>
  <joint
    name="TibiaRD_joint"
    type="revolute">
    <origin
      xyz="0.05395 0 0.0016"
      rpy="0 0 -1.5708" />
    <parent
      link="FemurRD_link" />
    <child
      link="TibiaRD_link" />
    <axis
      xyz="0 0 -1" />
    <limit
      lower="-1.57"
      upper="0.3925"
      effort="300"
      velocity="3" />
  </joint>
  <link
    name="RuedaRD_link">
    <inertial>
      <origin
        xyz="-0.0022780147213019610 0.0025475072051861510 -0.0063190359493592308"
        rpy="0 0 0" />
      <mass
        value="0.0405034383813952" />
      <inertia
        ixx="0.005174137497296206"
        ixy="0.0068457155408163413"
        ixz="0.002137818453735414"
        iyy="0.0051741383388720806"
        iyz="0.0066069143859850515"
        izz="0.0097299113209887606" />
    </inertial>
    <visual>
      <origin
        xyz="0 0 0"
        rpy="0 0 0" />
      <geometry>
        <mesh
          filename="package://peter_robot/meshes/RuedaRD_link.STL" />
      </geometry>
      <material
        name="">
        <color
          rgba="0.792156862745098 0.819607843137255 0.933333333333333 1" />
      </material>
    </visual>
    <collision>
      <origin
        xyz="0 0 0"
        rpy="0 0 0" />
      <geometry>
        <mesh
          filename="package://peter_robot/meshes/RuedaRD_link.STL" />
      </geometry>
    </collision>
  </link>
  <joint
    name="RuedaRD_joint"
    type="continuous">
    <origin
      xyz="0.07225 0 -0.0039"
      rpy="0 1.5708 0" />
    <parent
      link="TibiaRD_link" />
    <child
      link="RuedaRD_link" />
    <axis
      xyz="0 0 -1" />
  </joint>
  <link
    name="CoxisLD_link">
    <inertial>
      <origin
        xyz="0.0145758034287634 -0.000148324186440819 -0.00157951131109748"
        rpy="0 0 0" />
      <mass
        value="0.0198300229322089" />
      <inertia
        ixx="0.003320388730206"
        ixy="0.0074374350824844708"
        ixz="0.0056481316618717208"
        iyy="0.0046818529625022906"
        iyz="-0.0059763447978343810"
        izz="0.0062779650837921106" />
    </inertial>
    <visual>
      <origin
        xyz="0 0 0"
        rpy="0 0 0" />
      <geometry>
        <mesh
          filename="package://peter_robot/meshes/CoxisLD_link.STL" />
      </geometry>
      <material
        name="">
        <color
          rgba="0.792156862745098 0.819607843137255 0.933333333333333 1" />
      </material>
    </visual>
    <collision>
      <origin
        xyz="0 0 0"
        rpy="0 0 0" />
      <geometry>
        <mesh
          filename="package://peter_robot/meshes/CoxisLD_link.STL" />
      </geometry>
    </collision>
  </link>
  <joint
    name="CoxisLD_joint"
    type="revolute">
    <origin
      xyz="-0.0557999999999999 0.0558000000000001 0.02"
      rpy="3.14159265358979 0 1.5707963267949" />
    <parent
      link="base_link" />
    <child
      link="CoxisLD_link" />
    <axis
      xyz="0 0 -1" />
    <limit
      lower="0"
      upper="1.57"
      effort="300"
      velocity="3" />
  </joint>
  <link
    name="FemurLD_link">
    <inertial>
      <origin
        xyz="0.0158446271347616 0.000731589548341318 -0.00234896628844949"
        rpy="0 0 0" />
      <mass
        value="0.0267646480993488" />
      <inertia
        ixx="0.0027372725869173606"
        ixy="0.0031908240034705407"
        ixz="0.0085342307149318207"
        iyy="0.0073568709609241106"
        iyz="-0.0032602627566903708"
        izz="0.0075404497946103606" />
    </inertial>
    <visual>
      <origin
        xyz="0 0 0"
        rpy="0 0 0" />
      <geometry>
        <mesh
          filename="package://peter_robot/meshes/FemurLD_link.STL" />
      </geometry>
      <material
        name="">
        <color
          rgba="1 1 1 1" />
      </material>
    </visual>
    <collision>
      <origin
        xyz="0 0 0"
        rpy="0 0 0" />
      <geometry>
        <mesh
          filename="package://peter_robot/meshes/FemurLD_link.STL" />
      </geometry>
    </collision>
  </link>
  <joint
    name="FemurLD_joint"
    type="revolute">
    <origin
      xyz="0.0445499999999999 0 -0.00459999999999999"
      rpy="-1.5707963267949 0 0" />
    <parent
      link="CoxisLD_link" />
    <child
      link="FemurLD_link" />
    <axis
      xyz="0 0 -1" />
    <limit
      lower="-0.725"
      upper="0.725"
      effort="300"
      velocity="3" />
  </joint>
  <link
    name="TibiaLD_link">
    <inertial>
      <origin
        xyz="0.0303344390126996 -0.0064645429165843806 0.000537444120214961"
        rpy="0 0 0" />
      <mass
        value="0.0203567389458481" />
      <inertia
        ixx="0.0010753095603793906"
        ixy="0.0040815514175290412"
        ixz="-0.0072023646401669108"
        iyy="0.0035902033081829706"
        iyz="0.0080608997546156212"
        izz="0.0037227584821212906" />
    </inertial>
    <visual>
      <origin
        xyz="0 0 0"
        rpy="0 0 0" />
      <geometry>
        <mesh
          filename="package://peter_robot/meshes/TibiaLD_link.STL" />
      </geometry>
      <material
        name="">
        <color
          rgba="0.792156862745098 0.819607843137255 0.933333333333333 1" />
      </material>
    </visual>
    <collision>
      <origin
        xyz="0 0 0"
        rpy="0 0 0" />
      <geometry>
        <mesh
          filename="package://peter_robot/meshes/TibiaLD_link.STL" />
      </geometry>
    </collision>
  </link>
  <joint
    name="TibiaLD_joint"
    type="revolute">
    <origin
      xyz="0.0539500000000001 0 -0.00159999999999993"
      rpy="0 0 -1.5707963267949" />
    <parent
      link="FemurLD_link" />
    <child
      link="TibiaLD_link" />
    <axis
      xyz="0 0 -1" />
    <limit
      lower="-1.57"
      upper="0.3925"
      effort="300"
      velocity="3" />
  </joint>
  <link
    name="RuedaLD_link">
    <inertial>
      <origin
        xyz="0.002278017288692710 -0.0025475085929649310 -0.0063190356197617708"
        rpy="0 0 0" />
      <mass
        value="0.0405034383813952" />
      <inertia
        ixx="0.0051741374972961906"
        ixy="0.0068457155467389613"
        ixz="-0.0021378185041981414"
        iyy="0.0051741383388720806"
        iyz="-0.0066069141633005815"
        izz="0.0097299113209887706" />
    </inertial>
    <visual>
      <origin
        xyz="0 0 0"
        rpy="0 0 0" />
      <geometry>
        <mesh
          filename="package://peter_robot/meshes/RuedaLD_link.STL" />
      </geometry>
      <material
        name="">
        <color
          rgba="0.792156862745098 0.819607843137255 0.933333333333333 1" />
      </material>
    </visual>
    <collision>
      <origin
        xyz="0 0 0"
        rpy="0 0 0" />
      <geometry>
        <mesh
          filename="package://peter_robot/meshes/RuedaLD_link.STL" />
      </geometry>
    </collision>
  </link>
  <joint
    name="RuedaLD_joint"
    type="continuous">
    <origin
      xyz="0.0722499993139122 0 -0.00070000009500111"
      rpy="0 -1.5707963267949 0" />
    <parent
      link="TibiaLD_link" />
    <child
      link="RuedaLD_link" />
    <axis
      xyz="0 0 -1" />
  </joint>
</robot>